Workbook
Name battery_capacity: battery_capacity!$B$4:$U$4
Name h_trailer_hwmMSRP: MSRP1!$B$4:$T$4
Name volum: volume!$B$4:$U$4

Sheet yearFC
B1: DICE | C1: NGICE | D1: BEVF350 | E1: BEVF510 | F1: BEVE510 | G1: BEVF600 | H1: BEVF730 | I1: BEVF800 | J1: BEVF900 | K1: PHEV | L1: EDPHEV | M1: ELPHEV | N1: FCPHEV | O1: FCEV | P1: MICE | Q1: EDICE | R1: ELICE | S1: H2ICE35 | T1: H2ICE70 | U1: NH3ICE | V1: HNICE | Y1: DICEV | Z1: LNGV | AA1: BEV | AB1: FCEV | AC1: H2ICEV | AD1: MICEV | AF1: 百公里消耗能量密度MJ/100km | AG1: DICEV | AH1: LNGV | AI1: BEV | AJ1: FCEV | AK1: H2ICEV | AL1: MICEV
A2: 2018 | B2: 1.0933333 | C2: 1.56 | D2: 1.05 | E2: 1.07 | F2: =E2 -> 1.07 | G2: =E2 -> 1.07 | H2: =E2 -> 1.07 | I2: =E2 -> 1.07 | J2: =E2 -> 1.07 | K2: 1.07 | L2: =B2 -> 1.0933333 | M2: =C2 -> 1.56 | N2: 1.63 | O2: 1.11725 | P2: 1.28 | Q2: =B2 -> 1.0933333 | R2: =C2 -> 1.56 | S2: =O2 -> 1.11725 | T2: =O2 -> 1.11725 | U2: 1.35 | V2: 1.35 | X2: 2018 | Y2: =B2*38 -> 41.546667 | Z2: =C2*72 -> 112.32 | AA2: =H2*135 -> 144.45 | AB2: =O2*9 -> 10.05525 | AC2: =T2*11 -> 12.28975 | AD2: =110*P2 -> 140.8 | AE2: 使用车辆领域低热值转换 | AF2: 引用 | AG2: =Y2*35.8 -> 1487.3707 | AH2: =Z2*24 -> 2695.68 | AI2: =AA2*3.6 -> 520.02 | AJ2: =AB2*120 -> 1206.63 | AK2: =AC2*120 -> 1474.77 | AL2: =AD2*15.8 -> 2224.64
A3: 2019 | B3: 1.08 | C3: 1.48 | D3: 1.04 | E3: 1.06 | F3: =E3 -> 1.06 | G3: =E3 -> 1.06 | H3: =E3 -> 1.06 | I3: =E3 -> 1.06 | J3: =E3 -> 1.06 | K3: 1.06 | L3: =B3 -> 1.08 | M3: =C3 -> 1.48 | N3: 1.54 | O3: 1.1005 | P3: 1.24 | Q3: =B3 -> 1.08 | R3: =C3 -> 1.48 | S3: =O3 -> 1.1005 | T3: =O3 -> 1.1005 | U3: 1.3 | V3: 1.3 | X3: 2019 | Y3: =B3*38 -> 41.04 | Z3: =C3*72 -> 106.56 | AA3: =H3*135 -> 143.1 | AB3: =O3*9 -> 9.9045 | AC3: =T3*11 -> 12.1055 | AD3: =110*P3 -> 136.4 | AE3: 柴油 | AF3: ASTM D975 | AG3: =Y3*35.8 -> 1469.232 | AH3: =Z3*24 -> 2557.44 | AI3: =AA3*3.6 -> 515.16 | AJ3: =AB3*120 -> 1188.54 | AK3: =AC3*120 -> 1452.66 | AL3: =AD3*15.8 -> 2155.12
A4: 2020 | B4: 1.0666667 | C4: 1.4 | D4: 1.03 | E4: 1.05 | F4: =E4 -> 1.05 | G4: =E4 -> 1.05 | H4: =E4 -> 1.05 | I4: =E4 -> 1.05 | J4: =E4 -> 1.05 | K4: 1.05 | L4: =B4 -> 1.0666667 | M4: =C4 -> 1.4 | N4: 1.45 | O4: 1.08375 | P4: 1.2 | Q4: =B4 -> 1.0666667 | R4: =C4 -> 1.4 | S4: =O4 -> 1.08375 | T4: =O4 -> 1.08375 | U4: 1.25 | V4: 1.25 | X4: 2020 | Y4: =B4*38 -> 40.533333 | Z4: =C4*72 -> 100.8 | AA4: =H4*135 -> 141.75 | AB4: =O4*9 -> 9.75375 | AC4: =T4*11 -> 11.92125 | AD4: =110*P4 -> 132 | AE4: LNG | AF4: 国际气体联合会（IGU）：《LNG手册》（2023版）基于甲烷体积能量密度（纯甲烷：23.9–24.4 MJ/L），考虑典型LNG成分（甲烷占比>90%）取中值 | AG4: =Y4*35.8 -> 1451.0933 | AH4: =Z4*24 -> 2419.2 | AI4: =AA4*3.6 -> 510.3 | AJ4: =AB4*120 -> 1170.45 | AK4: =AC4*120 -> 1430.55 | AL4: =AD4*15.8 -> 2085.6
A5: 2021 | B5: 1.0533333 | C5: 1.32 | D5: 1.02 | E5: 1.04 | F5: =E5 -> 1.04 | G5: =E5 -> 1.04 | H5: =E5 -> 1.04 | I5: =E5 -> 1.04 | J5: =E5 -> 1.04 | K5: 1.04 | L5: =B5 -> 1.0533333 | M5: =C5 -> 1.32 | N5: 1.36 | O5: 1.067 | P5: 1.16 | Q5: =B5 -> 1.0533333 | R5: =C5 -> 1.32 | S5: =O5 -> 1.067 | T5: =O5 -> 1.067 | U5: 1.2 | V5: 1.2 | X5: 2021 | Y5: =B5*38 -> 40.026667 | Z5: =C5*72 -> 95.04 | AA5: =H5*135 -> 140.4 | AB5: =O5*9 -> 9.603 | AC5: =T5*11 -> 11.737 | AD5: =110*P5 -> 127.6 | AE5: BEV | AF5: 国际单位制（SI） | AG5: =Y5*35.8 -> 1432.9547 | AH5: =Z5*24 -> 2280.96 | AI5: =AA5*3.6 -> 505.44 | AJ5: =AB5*120 -> 1152.36 | AK5: =AC5*120 -> 1408.44 | AL5: =AD5*15.8 -> 2016.08
A6: 2022 | B6: 1.04 | C6: 1.24 | D6: 1.01 | E6: 1.03 | F6: =E6 -> 1.03 | G6: =E6 -> 1.03 | H6: =E6 -> 1.03 | I6: =E6 -> 1.03 | J6: =E6 -> 1.03 | K6: 1.03 | L6: =B6 -> 1.04 | M6: =C6 -> 1.24 | N6: 1.27 | O6: 1.05025 | P6: 1.12 | Q6: =B6 -> 1.04 | R6: =C6 -> 1.24 | S6: =O6 -> 1.05025 | T6: =O6 -> 1.05025 | U6: 1.15 | V6: 1.15 | X6: 2022 | Y6: =B6*38 -> 39.52 | Z6: =C6*72 -> 89.28 | AA6: =H6*135 -> 139.05 | AB6: =O6*9 -> 9.45225 | AC6: =T6*11 -> 11.55275 | AD6: =110*P6 -> 123.2 | AE6: FCEV | AF6: SAE J2578标准 | AG6: =Y6*35.8 -> 1414.816 | AH6: =Z6*24 -> 2142.72 | AI6: =AA6*3.6 -> 500.58 | AJ6: =AB6*120 -> 1134.27 | AK6: =AC6*120 -> 1386.33 | AL6: =AD6*15.8 -> 1946.56
A7: 2023 | B7: 1.0266667 | C7: 1.16 | D7: 1 | E7: 1.02 | F7: =E7 -> 1.02 | G7: =E7 -> 1.02 | H7: =E7 -> 1.02 | I7: =E7 -> 1.02 | J7: =E7 -> 1.02 | K7: 1.02 | L7: =B7 -> 1.0266667 | M7: =C7 -> 1.16 | N7: 1.18 | O7: 1.0335 | P7: 1.08 | Q7: =B7 -> 1.0266667 | R7: =C7 -> 1.16 | S7: =O7 -> 1.0335 | T7: =O7 -> 1.0335 | U7: 1.1 | V7: 1.1 | X7: 2023 | Y7: =B7*38 -> 39.013333 | Z7: =C7*72 -> 83.52 | AA7: =H7*135 -> 137.7 | AB7: =O7*9 -> 9.3015 | AC7: =T7*11 -> 11.3685 | AD7: =110*P7 -> 118.8 | AE7: H2ICEV | AG7: =Y7*35.8 -> 1396.6773 | AH7: =Z7*24 -> 2004.48 | AI7: =AA7*3.6 -> 495.72 | AJ7: =AB7*120 -> 1116.18 | AK7: =AC7*120 -> 1364.22 | AL7: =AD7*15.8 -> 1877.04
A8: 2024 | B8: 1.0133333 | C8: 1.08 | D8: 0.985 | E8: 1.01 | F8: =E8 -> 1.01 | G8: =E8 -> 1.01 | H8: =E8 -> 1.01 | I8: =E8 -> 1.01 | J8: =E8 -> 1.01 | K8: 1.01 | L8: =B8 -> 1.0133333 | M8: =C8 -> 1.08 | N8: 1.09 | O8: 1.01675 | P8: 1.04 | Q8: =B8 -> 1.0133333 | R8: =C8 -> 1.08 | S8: =O8 -> 1.01675 | T8: =O8 -> 1.01675 | U8: 1.05 | V8: 1.05 | X8: 2024 | Y8: =B8*38 -> 38.506667 | Z8: =C8*72 -> 77.76 | AA8: =H8*135 -> 136.35 | AB8: =O8*9 -> 9.15075 | AC8: =T8*11 -> 11.18425 | AD8: =110*P8 -> 114.4 | AE8: MICEV | AF8: 国际可再生能源机构（IRENA）：《甲醇燃料生命周期评估》（2023）基于密度0.791 kg/L及质量能量密度19.9 MJ/kg（LHV）计算得出.中国国标GB/T 23510-2009：车用甲醇燃料（M100）要求低热值≥15.0 MJ/L | AG8: =Y8*35.8 -> 1378.5387 | AH8: =Z8*24 -> 1866.24 | AI8: =AA8*3.6 -> 490.86 | AJ8: =AB8*120 -> 1098.09 | AK8: =AC8*120 -> 1342.11 | AL8: =AD8*15.8 -> 1807.52
A9: 2025 | B9: 1 | C9: 1 | D9: 1 | E9: 1 | F9: =E9 -> 1 | G9: =E9 -> 1 | H9: =E9 -> 1 | I9: =E9 -> 1 | J9: =E9 -> 1 | K9: 1 | L9: 1 | M9: 1 | N9: 1 | O9: 1 | P9: 1 | Q9: 1 | R9: 1 | S9: 1 | T9: =O9 -> 1 | U9: 1 | V9: 1 | X9: 2025 | Y9: =B9*38 -> 38 | Z9: =C9*72 -> 72 | AA9: =H9*135 -> 135 | AB9: =O9*9 -> 9 | AC9: =T9*11 -> 11 | AD9: =110*P9 -> 110 | AG9: =Y9*35.8 -> 1360.4 | AH9: =Z9*24 -> 1728 | AI9: =AA9*3.6 -> 486 | AJ9: =AB9*120 -> 1080 | AK9: =AC9*120 -> 1320 | AL9: =AD9*15.8 -> 1738 | AN9: 1 | AO9: 1 | AP9: 1 | AR9: =AN9*72 -> 72 | AS9: =AO9*72 -> 72 | AT9: =AP9*72 -> 72
A10: 2026 | B10: 0.99 | C10: 0.99 | D10: 0.99 | E10: 0.99333333 | F10: =E10 -> 0.99333333 | G10: =E10 -> 0.99333333 | H10: =E10 -> 0.99333333 | I10: =E10 -> 0.99333333 | J10: =E10 -> 0.99333333 | K10: 0.99 | L10: 0.99 | M10: 0.99 | N10: 0.99 | O10: 0.99 | P10: 0.99 | Q10: 0.99 | R10: 0.99 | S10: 0.99 | T10: =O10 -> 0.99 | U10: 1 | V10: 1 | X10: 2026 | Y10: =B10*38 -> 37.62 | Z10: =C10*72 -> 71.28 | AA10: =H10*135 -> 134.1 | AB10: =O10*9 -> 8.91 | AC10: =T10*11 -> 10.89 | AD10: =110*P10 -> 108.9 | AG10: =Y10*35.8 -> 1346.796 | AH10: =Z10*24 -> 1710.72 | AI10: =AA10*3.6 -> 482.76 | AJ10: =AB10*120 -> 1069.2 | AK10: =AC10*120 -> 1306.8 | AL10: =AD10*15.8 -> 1720.62 | AN10: 0.99 | AO10: 0.99142857 | AP10: 0.98857143 | AR10: =AN10*72 -> 71.28 | AS10: =AO10*72 -> 71.382857 | AT10: =AP10*72 -> 71.177143
A11: 2027 | B11: 0.98 | C11: 0.98 | D11: 0.98 | E11: 0.98666667 | F11: =E11 -> 0.98666667 | G11: =E11 -> 0.98666667 | H11: =E11 -> 0.98666667 | I11: =E11 -> 0.98666667 | J11: =E11 -> 0.98666667 | K11: 0.98 | L11: 0.98 | M11: 0.98 | N11: 0.98 | O11: 0.98 | P11: 0.98 | Q11: 0.98 | R11: 0.98 | S11: 0.98 | T11: =O11 -> 0.98 | U11: 1 | V11: 1 | X11: 2027 | Y11: =B11*38 -> 37.24 | Z11: =C11*72 -> 70.56 | AA11: =H11*135 -> 133.2 | AB11: =O11*9 -> 8.82 | AC11: =T11*11 -> 10.78 | AD11: =110*P11 -> 107.8 | AG11: =Y11*35.8 -> 1333.192 | AH11: =Z11*24 -> 1693.44 | AI11: =AA11*3.6 -> 479.52 | AJ11: =AB11*120 -> 1058.4 | AK11: =AC11*120 -> 1293.6 | AL11: =AD11*15.8 -> 1703.24 | AN11: 0.98 | AO11: 0.98285714 | AP11: 0.97714286 | AR11: =AN11*72 -> 70.56 | AS11: =AO11*72 -> 70.765714 | AT11: =AP11*72 -> 70.354286
A12: 2028 | B12: 0.97 | C12: 0.97 | D12: 0.97 | E12: 0.98 | F12: =E12 -> 0.98 | G12: =E12 -> 0.98 | H12: =E12 -> 0.98 | I12: =E12 -> 0.98 | J12: =E12 -> 0.98 | K12: 0.97 | L12: 0.97 | M12: 0.97 | N12: 0.97 | O12: 0.97 | P12: 0.97 | Q12: 0.97 | R12: 0.97 | S12: 0.97 | T12: =O12 -> 0.97 | U12: 1 | V12: 1 | X12: 2028 | Y12: =B12*38 -> 36.86 | Z12: =C12*72 -> 69.84 | AA12: =H12*135 -> 132.3 | AB12: =O12*9 -> 8.73 | AC12: =T12*11 -> 10.67 | AD12: =110*P12 -> 106.7 | AG12: =Y12*35.8 -> 1319.588 | AH12: =Z12*24 -> 1676.16 | AI12: =AA12*3.6 -> 476.28 | AJ12: =AB12*120 -> 1047.6 | AK12: =AC12*120 -> 1280.4 | AL12: =AD12*15.8 -> 1685.86 | AN12: 0.97 | AO12: 0.97428571 | AP12: 0.96571429 | AR12: =AN12*72 -> 69.84 | AS12: =AO12*72 -> 70.148571 | AT12: =AP12*72 -> 69.531429
A13: 2029 | B13: 0.96 | C13: 0.96 | D13: 0.96 | E13: 0.97333333 | F13: =E13 -> 0.97333333 | G13: =E13 -> 0.97333333 | H13: =E13 -> 0.97333333 | I13: =E13 -> 0.97333333 | J13: =E13 -> 0.97333333 | K13: 0.96 | L13: 0.96 | M13: 0.96 | N13: 0.96 | O13: 0.96 | P13: 0.96 | Q13: 0.96 | R13: 0.96 | S13: 0.96 | T13: =O13 -> 0.96 | U13: 1 | V13: 1 | X13: 2029 | Y13: =B13*38 -> 36.48 | Z13: =C13*72 -> 69.12 | AA13: =H13*135 -> 131.4 | AB13: =O13*9 -> 8.64 | AC13: =T13*11 -> 10.56 | AD13: =110*P13 -> 105.6 | AG13: =Y13*35.8 -> 1305.984 | AH13: =Z13*24 -> 1658.88 | AI13: =AA13*3.6 -> 473.04 | AJ13: =AB13*120 -> 1036.8 | AK13: =AC13*120 -> 1267.2 | AL13: =AD13*15.8 -> 1668.48 | AN13: 0.96 | AO13: 0.96571429 | AP13: 0.95428571 | AR13: =AN13*72 -> 69.12 | AS13: =AO13*72 -> 69.531429 | AT13: =AP13*72 -> 68.708571
A14: 2030 | B14: 0.95 | C14: 0.95 | D14: 0.95 | E14: 0.96666667 | F14: =E14 -> 0.96666667 | G14: =E14 -> 0.96666667 | H14: =E14 -> 0.96666667 | I14: =E14 -> 0.96666667 | J14: =E14 -> 0.96666667 | K14: 0.95 | L14: 0.95 | M14: 0.95 | N14: 0.95 | O14: 0.95 | P14: 0.95 | Q14: 0.89 | R14: 0.89 | S14: 0.89 | T14: =O14 -> 0.95 | U14: 1 | V14: 1 | X14: 2030 | Y14: =B14*38 -> 36.1 | Z14: =C14*72 -> 68.4 | AA14: =H14*135 -> 130.5 | AB14: =O14*9 -> 8.55 | AC14: =T14*11 -> 10.45 | AD14: =110*P14 -> 104.5 | AG14: =Y14*35.8 -> 1292.38 | AH14: =Z14*24 -> 1641.6 | AI14: =AA14*3.6 -> 469.8 | AJ14: =AB14*120 -> 1026 | AK14: =AC14*120 -> 1254 | AL14: =AD14*15.8 -> 1651.1 | AN14: 0.95 | AO14: 0.95714286 | AP14: 0.94285714 | AR14: =AN14*72 -> 68.4 | AS14: =AO14*72 -> 68.914286 | AT14: =AP14*72 -> 67.885714
A15: 2031 | B15: 0.94 | C15: 0.94 | D15: 0.94 | E15: 0.96 | F15: =E15 -> 0.96 | G15: =E15 -> 0.96 | H15: =E15 -> 0.96 | I15: =E15 -> 0.96 | J15: =E15 -> 0.96 | K15: 0.94 | L15: 0.94 | M15: 0.94 | N15: 0.94 | O15: 0.94 | P15: 0.94 | Q15: 0.94 | R15: 0.94 | S15: 0.94 | T15: =O15 -> 0.94 | U15: 1 | V15: 1 | X15: 2031 | Y15: =B15*38 -> 35.72 | Z15: =C15*72 -> 67.68 | AA15: =H15*135 -> 129.6 | AB15: =O15*9 -> 8.46 | AC15: =T15*11 -> 10.34 | AD15: =110*P15 -> 103.4 | AG15: =Y15*35.8 -> 1278.776 | AH15: =Z15*24 -> 1624.32 | AI15: =AA15*3.6 -> 466.56 | AJ15: =AB15*120 -> 1015.2 | AK15: =AC15*120 -> 1240.8 | AL15: =AD15*15.8 -> 1633.72 | AN15: 0.94 | AO15: 0.94857143 | AP15: 0.93142857 | AR15: =AN15*72 -> 67.68 | AS15: =AO15*72 -> 68.297143 | AT15: =AP15*72 -> 67.062857
A16: 2032 | B16: 0.93 | C16: 0.93 | D16: 0.93 | E16: 0.95333333 | F16: =E16 -> 0.95333333 | G16: =E16 -> 0.95333333 | H16: =E16 -> 0.95333333 | I16: =E16 -> 0.95333333 | J16: =E16 -> 0.95333333 | K16: 0.93 | L16: 0.93 | M16: 0.93 | N16: 0.93 | O16: 0.93 | P16: 0.93 | Q16: 0.93 | R16: 0.93 | S16: 0.93 | T16: =O16 -> 0.93 | U16: 1 | V16: 1 | X16: 2032 | Y16: =B16*38 -> 35.34 | Z16: =C16*72 -> 66.96 | AA16: =H16*135 -> 128.7 | AB16: =O16*9 -> 8.37 | AC16: =T16*11 -> 10.23 | AD16: =110*P16 -> 102.3 | AG16: =Y16*35.8 -> 1265.172 | AH16: =Z16*24 -> 1607.04 | AI16: =AA16*3.6 -> 463.32 | AJ16: =AB16*120 -> 1004.4 | AK16: =AC16*120 -> 1227.6 | AL16: =AD16*15.8 -> 1616.34 | AN16: 0.93 | AO16: 0.94 | AP16: 0.92 | AR16: =AN16*72 -> 66.96 | AS16: =AO16*72 -> 67.68 | AT16: =AP16*72 -> 66.24
A17: 2033 | B17: 0.92 | C17: 0.92 | D17: 0.92 | E17: 0.94666667 | F17: =E17 -> 0.94666667 | G17: =E17 -> 0.94666667 | H17: =E17 -> 0.94666667 | I17: =E17 -> 0.94666667 | J17: =E17 -> 0.94666667 | K17: 0.92 | L17: 0.92 | M17: 0.92 | N17: 0.92 | O17: 0.92 | P17: 0.92 | Q17: 0.92 | R17: 0.92 | S17: 0.92 | T17: =O17 -> 0.92 | U17: 1 | V17: 1 | X17: 2033 | Y17: =B17*38 -> 34.96 | Z17: =C17*72 -> 66.24 | AA17: =H17*135 -> 127.8 | AB17: =O17*9 -> 8.28 | AC17: =T17*11 -> 10.12 | AD17: =110*P17 -> 101.2 | AG17: =Y17*35.8 -> 1251.568 | AH17: =Z17*24 -> 1589.76 | AI17: =AA17*3.6 -> 460.08 | AJ17: =AB17*120 -> 993.6 | AK17: =AC17*120 -> 1214.4 | AL17: =AD17*15.8 -> 1598.96 | AN17: 0.92 | AO17: 0.93142857 | AP17: 0.90857143 | AR17: =AN17*72 -> 66.24 | AS17: =AO17*72 -> 67.062857 | AT17: =AP17*72 -> 65.417143
A18: 2034 | B18: 0.91 | C18: 0.91 | D18: 0.91 | E18: 0.94 | F18: =E18 -> 0.94 | G18: =E18 -> 0.94 | H18: =E18 -> 0.94 | I18: =E18 -> 0.94 | J18: =E18 -> 0.94 | K18: 0.91 | L18: 0.91 | M18: 0.91 | N18: 0.91 | O18: 0.91 | P18: 0.91 | Q18: 0.91 | R18: 0.91 | S18: 0.91 | T18: =O18 -> 0.91 | U18: 0.91 | V18: 0.91 | X18: 2034 | Y18: =B18*38 -> 34.58 | Z18: =C18*72 -> 65.52 | AA18: =H18*135 -> 126.9 | AB18: =O18*9 -> 8.19 | AC18: =T18*11 -> 10.01 | AD18: =110*P18 -> 100.1 | AG18: =Y18*35.8 -> 1237.964 | AH18: =Z18*24 -> 1572.48 | AI18: =AA18*3.6 -> 456.84 | AJ18: =AB18*120 -> 982.8 | AK18: =AC18*120 -> 1201.2 | AL18: =AD18*15.8 -> 1581.58 | AN18: 0.91 | AO18: 0.92285714 | AP18: 0.89714286 | AR18: =AN18*72 -> 65.52 | AS18: =AO18*72 -> 66.445714 | AT18: =AP18*72 -> 64.594286
A19: 2035 | B19: 0.9 | C19: 0.9 | D19: 0.9 | E19: 0.93333333 | F19: =E19 -> 0.93333333 | G19: =E19 -> 0.93333333 | H19: =E19 -> 0.93333333 | I19: =E19 -> 0.93333333 | J19: =E19 -> 0.93333333 | K19: 0.9 | L19: 0.9 | M19: 0.9 | N19: 0.9 | O19: 0.9 | P19: 0.9 | Q19: 0.9 | R19: 0.9 | S19: 0.9 | T19: =O19 -> 0.9 | U19: 0.9 | V19: 0.9 | X19: 2035 | Y19: =B19*38 -> 34.2 | Z19: =C19*72 -> 64.8 | AA19: =H19*135 -> 126 | AB19: =O19*9 -> 8.1 | AC19: =T19*11 -> 9.9 | AD19: =110*P19 -> 99 | AG19: =Y19*35.8 -> 1224.36 | AH19: =Z19*24 -> 1555.2 | AI19: =AA19*3.6 -> 453.6 | AJ19: =AB19*120 -> 972 | AK19: =AC19*120 -> 1188 | AL19: =AD19*15.8 -> 1564.2 | AN19: 0.9 | AO19: 0.91428571 | AP19: 0.88571429 | AR19: =AN19*72 -> 64.8 | AS19: =AO19*72 -> 65.828571 | AT19: =AP19*72 -> 63.771429
A20: 2036 | B20: 0.89 | C20: 0.89 | D20: 0.89 | E20: 0.92666667 | F20: =E20 -> 0.92666667 | G20: =E20 -> 0.92666667 | H20: =E20 -> 0.92666667 | I20: =E20 -> 0.92666667 | J20: =E20 -> 0.92666667 | K20: 0.89 | L20: 0.89 | M20: 0.89 | N20: 0.89 | O20: 0.89 | P20: 0.89 | Q20: 0.89 | R20: 0.89 | S20: 0.89 | T20: =O20 -> 0.89 | U20: 0.89 | V20: 0.89 | X20: 2036 | Y20: =B20*38 -> 33.82 | Z20: =C20*72 -> 64.08 | AA20: =H20*135 -> 125.1 | AB20: =O20*9 -> 8.01 | AC20: =T20*11 -> 9.79 | AD20: =110*P20 -> 97.9 | AG20: =Y20*35.8 -> 1210.756 | AH20: =Z20*24 -> 1537.92 | AI20: =AA20*3.6 -> 450.36 | AJ20: =AB20*120 -> 961.2 | AK20: =AC20*120 -> 1174.8 | AL20: =AD20*15.8 -> 1546.82 | AN20: 0.89 | AO20: 0.90571429 | AP20: 0.87428571 | AR20: =AN20*72 -> 64.08 | AS20: =AO20*72 -> 65.211429 | AT20: =AP20*72 -> 62.948571
... A29: 2045 | B29: 0.8 | C29: 0.8 | D29: 0.8 | E29: 0.86666667 | F29: =E29 -> 0.86666667 | G29: =E29 -> 0.86666667 | H29: =E29 -> 0.86666667 | I29: =E29 -> 0.86666667 | J29: =E29 -> 0.86666667 | K29: 0.8 | L29: 0.8 | M29: 0.8 | N29: 0.8 | O29: 0.785 | P29: 0.8 | Q29: 0.8 | R29: 0.8 | S29: 0.8 | T29: =O29 -> 0.785 | U29: 0.8 | V29: 0.8 | X29: 2045 | Y29: =B29*38 -> 30.4 | Z29: =C29*72 -> 57.6 | AA29: =H29*135 -> 117 | AB29: =O29*9 -> 7.065 | AC29: =T29*11 -> 8.635 | AD29: =110*P29 -> 88 | AG29: =Y29*35.8 -> 1088.32 | AH29: =Z29*24 -> 1382.4 | AI29: =AA29*3.6 -> 421.2 | AJ29: =AB29*120 -> 847.8 | AK29: =AC29*120 -> 1036.2 | AL29: =AD29*15.8 -> 1390.4 | AN29: 0.8 | AO29: 0.82857143 | AP29: 0.77142857 | AR29: =AN29*72 -> 57.6 | AS29: =AO29*72 -> 59.657143 | AT29: =AP29*72 -> 55.542857
A30: 2046 | B30: 0.79 | C30: 0.79 | D30: 0.8 | E30: 0.86 | F30: =E30 -> 0.86 | G30: =E30 -> 0.86 | H30: =E30 -> 0.86 | I30: =E30 -> 0.86 | J30: =E30 -> 0.86 | K30: 0.79 | L30: 0.79 | M30: 0.79 | N30: 0.79 | O30: 0.772 | P30: 0.79 | Q30: 0.79 | R30: 0.79 | S30: 0.79 | T30: =O30 -> 0.772 | U30: 1 | V30: 1 | AN30: 0.79 | AO30: 0.82 | AP30: 0.76 | AR30: =AN30*72 -> 56.88 | AS30: =AO30*72 -> 59.04 | AT30: =AP30*72 -> 54.72
A31: 2047 | B31: 0.78 | C31: 0.78 | D31: 0.8 | E31: 0.85333333 | F31: =E31 -> 0.85333333 | G31: =E31 -> 0.85333333 | H31: =E31 -> 0.85333333 | I31: =E31 -> 0.85333333 | J31: =E31 -> 0.85333333 | K31: 0.78 | L31: 0.78 | M31: 0.78 | N31: 0.78 | O31: 0.759 | P31: 0.78 | Q31: 0.78 | R31: 0.78 | S31: 0.78 | T31: =O31 -> 0.759 | U31: 1 | V31: 1 | AN31: 0.78 | AO31: 0.81142857 | AP31: 0.74857143 | AR31: =AN31*72 -> 56.16 | AS31: =AO31*72 -> 58.422857 | AT31: =AP31*72 -> 53.897143
A32: 2048 | B32: 0.77 | C32: 0.77 | D32: 0.8 | E32: 0.84666667 | F32: =E32 -> 0.84666667 | G32: =E32 -> 0.84666667 | H32: =E32 -> 0.84666667 | I32: =E32 -> 0.84666667 | J32: =E32 -> 0.84666667 | K32: 0.77 | L32: 0.77 | M32: 0.77 | N32: 0.77 | O32: 0.746 | P32: 0.77 | Q32: 0.77 | R32: 0.77 | S32: 0.77 | T32: =O32 -> 0.746 | U32: 1 | V32: 1 | AN32: 0.77 | AO32: 0.80285714 | AP32: 0.73714286 | AR32: =AN32*72 -> 55.44 | AS32: =AO32*72 -> 57.805714 | AT32: =AP32*72 -> 53.074286
A33: 2049 | B33: 0.76 | C33: 0.76 | D33: 0.8 | E33: 0.84 | F33: =E33 -> 0.84 | G33: =E33 -> 0.84 | H33: =E33 -> 0.84 | I33: =E33 -> 0.84 | J33: =E33 -> 0.84 | K33: 0.76 | L33: 0.76 | M33: 0.76 | N33: 0.76 | O33: 0.733 | P33: 0.76 | Q33: 0.76 | R33: 0.76 | S33: 0.76 | T33: =O33 -> 0.733 | U33: 1 | V33: 1 | AN33: 0.76 | AO33: 0.79428571 | AP33: 0.72571429 | AR33: =AN33*72 -> 54.72 | AS33: =AO33*72 -> 57.188571 | AT33: =AP33*72 -> 52.251429
A34: 2050 | B34: 0.75 | C34: 0.75 | D34: 0.8 | E34: 0.83333333 | F34: =E34 -> 0.83333333 | G34: =E34 -> 0.83333333 | H34: =E34 -> 0.83333333 | I34: =E34 -> 0.83333333 | J34: =E34 -> 0.83333333 | K34: 0.75 | L34: 0.75 | M34: 0.75 | N34: 0.75 | O34: 0.72 | P34: 0.75 | Q34: 0.75 | R34: 0.75 | S34: 0.75 | T34: =O34 -> 0.72 | U34: 1 | V34: 1 | AN34: 0.75 | AO34: 0.78571429 | AP34: 0.71428571 | AR34: =AN34*72 -> 54 | AS34: =AO34*72 -> 56.571429 | AT34: =AP34*72 -> 51.428571
A35: 2051 | B35: 0.8 | C35: 0.8 | D35: 0.8 | E35: 0.82666667 | F35: =E35 -> 0.82666667 | G35: =E35 -> 0.82666667 | H35: =E35 -> 0.82666667 | I35: =E35 -> 0.82666667 | J35: =E35 -> 0.82666667 | K35: 0.8 | L35: 0.8 | M35: 0.8 | N35: 0.8 | O35: 0.8 | P35: 0.8 | Q35: 0.8 | R35: 0.8 | S35: 0.8 | T35: =O35 -> 0.8 | U35: 1 | V35: 1 | AN35: 0.8 | AO35: 0.77714286 | AP35: 0.70285714 | AR35: =AN35*72 -> 57.6 | AS35: =AO35*72 -> 55.954286 | AT35: =AP35*72 -> 50.605714
A36: 2052 | B36: 0.8 | C36: 0.8 | D36: 0.8 | E36: 0.82 | F36: =E36 -> 0.82 | G36: =E36 -> 0.82 | H36: =E36 -> 0.82 | I36: =E36 -> 0.82 | J36: =E36 -> 0.82 | K36: 0.8 | L36: 0.8 | M36: 0.8 | N36: 0.8 | O36: 0.8 | P36: 0.8 | Q36: 0.8 | R36: 0.8 | S36: 0.8 | T36: =O36 -> 0.8 | U36: 1 | V36: 1 | AN36: 0.8 | AO36: 0.76857143 | AP36: 0.69142857 | AR36: =AN36*72 -> 57.6 | AS36: =AO36*72 -> 55.337143 | AT36: =AP36*72 -> 49.782857
A37: 2053 | B37: 0.8 | C37: 0.8 | D37: 0.8 | E37: 0.81333333 | F37: =E37 -> 0.81333333 | G37: =E37 -> 0.81333333 | H37: =E37 -> 0.81333333 | I37: =E37 -> 0.81333333 | J37: =E37 -> 0.81333333 | K37: 0.8 | L37: 0.8 | M37: 0.8 | N37: 0.8 | O37: 0.8 | P37: 0.8 | Q37: 0.8 | R37: 0.8 | S37: 0.8 | T37: =O37 -> 0.8 | U37: 1 | V37: 1 | AN37: 0.8 | AO37: 0.76 | AP37: 0.68 | AR37: =AN37*72 -> 57.6 | AS37: =AO37*72 -> 54.72 | AT37: =AP37*72 -> 48.96
A38: 2054 | B38: 0.8 | C38: 0.8 | D38: 0.8 | E38: 0.80666667 | F38: =E38 -> 0.80666667 | G38: =E38 -> 0.80666667 | H38: =E38 -> 0.80666667 | I38: =E38 -> 0.80666667 | J38: =E38 -> 0.80666667 | K38: 0.8 | L38: 0.8 | M38: 0.8 | N38: 0.8 | O38: 0.8 | P38: 0.8 | Q38: 0.8 | R38: 0.8 | S38: 0.8 | T38: =O38 -> 0.8 | U38: 1 | V38: 1 | AN38: 0.8 | AO38: 0.75142857 | AP38: 0.66857143 | AR38: =AN38*72 -> 57.6 | AS38: =AO38*72 -> 54.102857 | AT38: =AP38*72 -> 48.137143
A39: 2055 | B39: 0.8 | C39: 0.8 | D39: 0.8 | E39: 0.8 | F39: =E39 -> 0.8 | G39: =E39 -> 0.8 | H39: =E39 -> 0.8 | I39: =E39 -> 0.8 | J39: =E39 -> 0.8 | K39: 0.8 | L39: 0.8 | M39: 0.8 | N39: 0.8 | O39: 0.8 | P39: 0.8 | Q39: 0.8 | R39: 0.8 | S39: 0.8 | T39: =O39 -> 0.8 | U39: 1 | V39: 1 | AN39: 0.8 | AO39: 0.74285714 | AP39: 0.65714286 | AR39: =AN39*72 -> 57.6 | AS39: =AO39*72 -> 53.485714 | AT39: =AP39*72 -> 47.314286
A40: 2056 | B40: 0.8 | C40: 0.8 | D40: 0.8 | E40: 0.79333333 | F40: =E40 -> 0.79333333 | G40: =E40 -> 0.79333333 | H40: =E40 -> 0.79333333 | I40: =E40 -> 0.79333333 | J40: =E40 -> 0.79333333 | K40: 0.8 | L40: 0.8 | M40: 0.8 | N40: 0.8 | O40: 0.8 | P40: 0.8 | Q40: 0.8 | R40: 0.8 | S40: 0.8 | T40: =O40 -> 0.8 | U40: 1 | V40: 1 | AN40: 0.8 | AO40: 0.73428571 | AP40: 0.64571429 | AR40: =AN40*72 -> 57.6 | AS40: =AO40*72 -> 52.868571 | AT40: =AP40*72 -> 46.491429
A41: 2057 | B41: 0.8 | C41: 0.8 | D41: 0.8 | E41: 0.78666667 | F41: =E41 -> 0.78666667 | G41: =E41 -> 0.78666667 | H41: =E41 -> 0.78666667 | I41: =E41 -> 0.78666667 | J41: =E41 -> 0.78666667 | K41: 0.8 | L41: 0.8 | M41: 0.8 | N41: 0.8 | O41: 0.8 | P41: 0.8 | Q41: 0.8 | R41: 0.8 | S41: 0.8 | T41: =O41 -> 0.8 | U41: 1 | V41: 1 | AN41: 0.8 | AO41: 0.72571429 | AP41: 0.63428571 | AR41: =AN41*72 -> 57.6 | AS41: =AO41*72 -> 52.251429 | AT41: =AP41*72 -> 45.668571
... A44: 2060 | B44: 0.8 | C44: 0.8 | D44: 0.8 | E44: 0.76666667 | F44: =E44 -> 0.76666667 | G44: =E44 -> 0.76666667 | H44: =E44 -> 0.76666667 | I44: =E44 -> 0.76666667 | J44: =E44 -> 0.76666667 | K44: 0.8 | L44: 0.8 | M44: 0.8 | N44: 0.8 | O44: 0.8 | P44: 0.8 | Q44: 0.8 | R44: 0.8 | S44: 0.8 | T44: =O44 -> 0.8 | U44: 1 | V44: 1 | AN44: 0.8 | AO44: 0.7 | AP44: 0.6 | AR44: =AN44*72 -> 57.6 | AS44: =AO44*72 -> 50.4 | AT44: =AP44*72 -> 43.2

Sheet temfc
B1: DICE | C1: NGICE | D1: BEVF510 | E1: BEVF600 | F1: BEVF730 | G1: BEVF800 | H1: BEVF900 | I1: BEVE510 | J1: EDPHEV | K1: ELPHEV | L1: FCEV | M1: MICE | N1: H2ICE70 | P1: 温度 | Q1: 20 | R1: 10 | S1: 0 | T1: -10 | U1: -20 | V1: -30
A2: 黑龙江 | B2: 1.5 | C2: 1.5 | D2: 1.5 | E2: 1.5 | F2: 1.5 | G2: 1.5 | H2: 1.5 | I2: 1.5 | J2: 1.5 | K2: 1.5 | L2: 1.5 | M2: 1.5 | N2: 1.5 | P2: 系数 | Q2: 1 | R2: 1.2 | S2: 1.5
A3: 吉林 | B3: 1.5 | C3: 1.5 | D3: 1.5 | E3: 1.5 | F3: 1.5 | G3: 1.5 | H3: 1.5 | I3: 1.5 | J3: 1.5 | K3: 1.5 | L3: 1.5 | M3: 1.5 | N3: 1.5
A4: 辽宁 | B4: 1.5 | C4: 1.5 | D4: 1.5 | E4: 1.5 | F4: 1.5 | G4: 1.5 | H4: 1.5 | I4: 1.5 | J4: 1.5 | K4: 1.5 | L4: 1.5 | M4: 1.5 | N4: 1.5
A5: 北京 | B5: 1.5 | C5: 1.5 | D5: 1.5 | E5: 1.5 | F5: 1.5 | G5: 1.5 | H5: 1.5 | I5: 1.5 | J5: 1.5 | K5: 1.5 | L5: 1.5 | M5: 1.5 | N5: 1.5
A6: 天津 | B6: 1.5 | C6: 1.5 | D6: 1.5 | E6: 1.5 | F6: 1.5 | G6: 1.5 | H6: 1.5 | I6: 1.5 | J6: 1.5 | K6: 1.5 | L6: 1.5 | M6: 1.5 | N6: 1.5
A7: 河北 | B7: 1.5 | C7: 1.5 | D7: 1.5 | E7: 1.5 | F7: 1.5 | G7: 1.5 | H7: 1.5 | I7: 1.5 | J7: 1.5 | K7: 1.5 | L7: 1.5 | M7: 1.5 | N7: 1.5
A8: 山西 | B8: 1.5 | C8: 1.5 | D8: 1.5 | E8: 1.5 | F8: 1.5 | G8: 1.5 | H8: 1.5 | I8: 1.5 | J8: 1.5 | K8: 1.5 | L8: 1.5 | M8: 1.5 | N8: 1.5
A9: 内蒙古 | B9: 1.5 | C9: 1.5 | D9: 1.5 | E9: 1.5 | F9: 1.5 | G9: 1.5 | H9: 1.5 | I9: 1.5 | J9: 1.5 | K9: 1.5 | L9: 1.5 | M9: 1.5 | N9: 1.5
A10: 新疆 | B10: 1.5 | C10: 1.5 | D10: 1.5 | E10: 1.5 | F10: 1.5 | G10: 1.5 | H10: 1.5 | I10: 1.5 | J10: 1.5 | K10: 1.5 | L10: 1.5 | M10: 1.5 | N10: 1.5
A11: 甘肃 | B11: 1.5 | C11: 1.5 | D11: 1.5 | E11: 1.5 | F11: 1.5 | G11: 1.5 | H11: 1.5 | I11: 1.5 | J11: 1.5 | K11: 1.5 | L11: 1.5 | M11: 1.5 | N11: 1.5
A12: 陕西 | B12: 1.5 | C12: 1.5 | D12: 1.5 | E12: 1.5 | F12: 1.5 | G12: 1.5 | H12: 1.5 | I12: 1.5 | J12: 1.5 | K12: 1.5 | L12: 1.5 | M12: 1.5 | N12: 1.5
A13: 宁夏 | B13: 1.5 | C13: 1.5 | D13: 1.5 | E13: 1.5 | F13: 1.5 | G13: 1.5 | H13: 1.5 | I13: 1.5 | J13: 1.5 | K13: 1.5 | L13: 1.5 | M13: 1.5 | N13: 1.5
A14: 青海 | B14: 1.5 | C14: 1.5 | D14: 1.5 | E14: 1.5 | F14: 1.5 | G14: 1.5 | H14: 1.5 | I14: 1.5 | J14: 1.5 | K14: 1.5 | L14: 1.5 | M14: 1.5 | N14: 1.5
... A32: 海南 | B32: 1.5 | C32: 1.5 | D32: 1.5 | E32: 1.5 | F32: 1.5 | G32: 1.5 | H32: 1.5 | I32: 1.5 | J32: 1.5 | K32: 1.5 | L32: 1.5 | M32: 1.5 | N32: 1.5

Sheet gradefc
B1: DICE | C1: NGICE | D1: BEVF510 | E1: BEVF600 | F1: BEVF730 | G1: BEVF800 | H1: BEVF900 | I1: BEVE510 | J1: EDPHEV | K1: ELPHEV | L1: FCEV | M1: MICE | N1: H2ICE70 | P1: 坡度 | Q1: 0 | R1: 0.1 | S1: 0.2 | T1: 0.3 | U1: 0.4 | V1: 0.5
A2: 黑龙江 | B2: 1 | C2: 1 | D2: 1 | E2: 1 | F2: 1 | G2: 1 | H2: 1 | I2: 1 | J2: 1 | K2: 1 | L2: 1 | M2: 1 | N2: 1 | P2: 系数 | Q2: 1 | R2: 1.2 | S2: 1.5
A3: 吉林 | B3: 1 | C3: 1 | D3: 1 | E3: 1 | F3: 1 | G3: 1 | H3: 1 | I3: 1 | J3: 1 | K3: 1 | L3: 1 | M3: 1 | N3: 1 | P3: 0
A4: 辽宁 | B4: 1 | C4: 1 | D4: 1 | E4: 1 | F4: 1 | G4: 1 | H4: 1 | I4: 1 | J4: 1 | K4: 1 | L4: 1 | M4: 1 | N4: 1 | P4: 0
A5: 北京 | B5: 1 | C5: 1 | D5: 1 | E5: 1 | F5: 1 | G5: 1 | H5: 1 | I5: 1 | J5: 1 | K5: 1 | L5: 1 | M5: 1 | N5: 1 | P5: 0
A6: 天津 | B6: 1 | C6: 1 | D6: 1 | E6: 1 | F6: 1 | G6: 1 | H6: 1 | I6: 1 | J6: 1 | K6: 1 | L6: 1 | M6: 1 | N6: 1 | P6: 0
A7: 河北 | B7: 1 | C7: 1 | D7: 1 | E7: 1 | F7: 1 | G7: 1 | H7: 1 | I7: 1 | J7: 1 | K7: 1 | L7: 1 | M7: 1 | N7: 1 | P7: 0
A8: 山西 | B8: 1 | C8: 1 | D8: 1 | E8: 1 | F8: 1 | G8: 1 | H8: 1 | I8: 1 | J8: 1 | K8: 1 | L8: 1 | M8: 1 | N8: 1 | P8: 0
A9: 内蒙古 | B9: 1 | C9: 1 | D9: 1 | E9: 1 | F9: 1 | G9: 1 | H9: 1 | I9: 1 | J9: 1 | K9: 1 | L9: 1 | M9: 1 | N9: 1 | P9: 0
A10: 新疆 | B10: 1 | C10: 1 | D10: 1 | E10: 1 | F10: 1 | G10: 1 | H10: 1 | I10: 1 | J10: 1 | K10: 1 | L10: 1 | M10: 1 | N10: 1 | P10: 0
A11: 甘肃 | B11: 1 | C11: 1 | D11: 1 | E11: 1 | F11: 1 | G11: 1 | H11: 1 | I11: 1 | J11: 1 | K11: 1 | L11: 1 | M11: 1 | N11: 1 | P11: 0
A12: 陕西 | B12: 1 | C12: 1 | D12: 1 | E12: 1 | F12: 1 | G12: 1 | H12: 1 | I12: 1 | J12: 1 | K12: 1 | L12: 1 | M12: 1 | N12: 1 | P12: 0
A13: 宁夏 | B13: 1 | C13: 1 | D13: 1 | E13: 1 | F13: 1 | G13: 1 | H13: 1 | I13: 1 | J13: 1 | K13: 1 | L13: 1 | M13: 1 | N13: 1 | P13: 0
A14: 青海 | B14: 1 | C14: 1 | D14: 1 | E14: 1 | F14: 1 | G14: 1 | H14: 1 | I14: 1 | J14: 1 | K14: 1 | L14: 1 | M14: 1 | N14: 1 | P14: 0
... A32: 海南 | B32: 1 | C32: 1 | D32: 1 | E32: 1 | F32: 1 | G32: 1 | H32: 1 | I32: 1 | J32: 1 | K32: 1 | L32: 1 | M32: 1 | N32: 1 | P32: 0

Sheet degradeFC
B1: DICE | C1: NGICE | D1: BEVF350 | E1: BEVF510 | F1: BEVE510 | G1: BEVF600 | H1: BEVF730 | I1: BEVF800 | J1: BEVF900 | K1: PHEV | L1: EDPHEV | M1: ELPHEV | N1: FCPHEV | O1: FCEV | P1: MICE | Q1: EDICE | R1: ELICE | S1: H2ICE35 | T1: H2ICE70 | V1: 假设一直以额定功率输出 | W1: 1年 | X1: 2年 | Y1: 3年 | Z1: 4年 | AA1: 5年 | AB1: 6年 | AF1: 2025年技术作为基准 | AG1: 年变化率来自Life Cycle Economic and Environmental Assessment for Emerging Heavy-Duty Truck Powertrain Technologies in China
A2: 2018 | B2: 1 | C2: 1 | D2: 1 | E2: 1 | F2: 1 | G2: 1 | H2: 1 | I2: 1 | J2: 1 | K2: 1 | L2: 1 | M2: 1 | N2: 1 | O2: 1.1616088 | P2: 1 | Q2: 1 | R2: 1 | S2: 1 | T2: 1 | V2: 使用小时 | W2: 1500 | X2: 3000 | Y2: 4500 | Z2: 6000 | AA2: 7500 | AB2: 9000 | AD2: Δ | AE2: fc | AF2: 衰减率来自The effects of driving patterns and PEM fuel cell degradation on the lifecycle assessment of hydrogen fuel cell vehicles
A3: 2019 | B3: 1 | C3: 1 | D3: 1 | E3: 1 | F3: 1 | G3: 1 | H3: 1 | I3: 1 | J3: 1 | K3: 1 | L3: 1 | M3: 1 | N3: 1 | O3: 1.1616088 | P3: 1 | Q3: 1 | R3: 1 | S3: 1 | T3: 1 | U3: 2025 | V3: end of life efficiency(衰减率取2.65E10-5 V/h） | W3: =W2*0.0000265 -> 0.03975 | X3: =X2*0.0000265 -> 0.0795 | Y3: =Y2*0.0000265 -> 0.11925 | Z3: =Z2*0.0000265 -> 0.159 | AA3: =AA2*0.0000265 -> 0.19875 | AB3: =AB2*0.0000265 -> 0.2385 | AC3: =AVERAGE(W3:AB3) -> 0.139125 | AD3: =400*AC3 -> 55.65 | AE3: =400/(400-AD3) -> 1.1616088 | AF3: 国内主流整车电压400v,
A4: 2020 | B4: 1 | C4: 1 | D4: 1 | E4: 1 | F4: 1 | G4: 1 | H4: 1 | I4: 1 | J4: 1 | K4: 1 | L4: 1 | M4: 1 | N4: 1 | O4: 1.1616088 | P4: 1 | Q4: 1 | R4: 1 | S4: 1 | T4: 1 | U4: 2030 | V4: end of life efficiency(衰减率取0.63*2.65E10-5 V/h） | W4: =0.63*W2*0.0000265 -> 0.0250425 | X4: =0.63*X2*0.0000265 -> 0.050085 | Y4: =0.63*Y2*0.0000265 -> 0.0751275 | Z4: =0.63*Z2*0.0000265 -> 0.10017 | AA4: =0.63*AA2*0.0000265 -> 0.1252125 | AB4: =0.63*AB2*0.0000265 -> 0.150255 | AC4: =AVERAGE(W4:AB4) -> 0.08764875 | AD4: =400*AC4 -> 35.0595 | AE4: =400/(400-AD4) -> 1.0960691
A5: 2021 | B5: 1 | C5: 1 | D5: 1 | E5: 1 | F5: 1 | G5: 1 | H5: 1 | I5: 1 | J5: 1 | K5: 1 | L5: 1 | M5: 1 | N5: 1 | O5: 1.1616088 | P5: 1 | Q5: 1 | R5: 1 | S5: 1 | T5: 1 | U5: 2035 | V5: end of life efficiency(衰减率取0.5*2.65E10-5 V/h） | W5: =0.5*W2*0.0000265 -> 0.019875 | X5: =0.5*X2*0.0000265 -> 0.03975 | Y5: =0.5*Y2*0.0000265 -> 0.059625 | Z5: =0.5*Z2*0.0000265 -> 0.0795 | AA5: =0.5*AA2*0.0000265 -> 0.099375 | AB5: =0.5*AB2*0.0000265 -> 0.11925 | AC5: =AVERAGE(W5:AB5) -> 0.0695625 | AD5: =400*AC5 -> 27.825 | AE5: =400/(400-AD5) -> 1.0747632
A6: 2022 | B6: 1 | C6: 1 | D6: 1 | E6: 1 | F6: 1 | G6: 1 | H6: 1 | I6: 1 | J6: 1 | K6: 1 | L6: 1 | M6: 1 | N6: 1 | O6: 1.1616088 | P6: 1 | Q6: 1 | R6: 1 | S6: 1 | T6: 1 | U6: 2040 | V6: end of life efficiency(衰减率取0.37*2.65E10-5 V/h,即1E-5V/h) | W6: =0.377*W2*0.0000265 -> 0.01498575 | X6: =0.377*X2*0.0000265 -> 0.0299715 | Y6: =0.377*Y2*0.0000265 -> 0.04495725 | Z6: =0.377*Z2*0.0000265 -> 0.059943 | AA6: =0.377*AA2*0.0000265 -> 0.07492875 | AB6: =0.377*AB2*0.0000265 -> 0.0899145 | AC6: =AVERAGE(W6:AB6) -> 0.052450125 | AD6: =400*AC6 -> 20.98005 | AE6: =400/(400-AD6) -> 1.0553534
A7: 2023 | B7: 1 | C7: 1 | D7: 1 | E7: 1 | F7: 1 | G7: 1 | H7: 1 | I7: 1 | J7: 1 | K7: 1 | L7: 1 | M7: 1 | N7: 1 | O7: 1.1616088 | P7: 1 | Q7: 1 | R7: 1 | S7: 1 | T7: 1 | U7: 2045=2040
A8: 2024 | B8: 1 | C8: 1 | D8: 1 | E8: 1 | F8: 1 | G8: 1 | H8: 1 | I8: 1 | J8: 1 | K8: 1 | L8: 1 | M8: 1 | N8: 1 | O8: 1.1616088 | P8: 1 | Q8: 1 | R8: 1 | S8: 1 | T8: 1
A9: 2025 | B9: 1 | C9: 1 | D9: 1 | E9: 1 | F9: 1 | G9: 1 | H9: 1 | I9: 1 | J9: 1 | K9: 1 | L9: 1 | M9: 1 | N9: 1 | O9: 1.1616088 | P9: 1 | Q9: 1 | R9: 1 | S9: 1 | T9: 1
A10: 2026 | B10: 1 | C10: 1 | D10: 1 | E10: 1 | F10: 1 | G10: 1 | H10: 1 | I10: 1 | J10: 1 | K10: 1 | L10: 1 | M10: 1 | N10: 1 | O10: 1.1485009 | P10: 1 | Q10: 1 | R10: 1 | S10: 1 | T10: 1 | V10: 国内主流整车电压400v,
A11: 2027 | B11: 1 | C11: 1 | D11: 1 | E11: 1 | F11: 1 | G11: 1 | H11: 1 | I11: 1 | J11: 1 | K11: 1 | L11: 1 | M11: 1 | N11: 1 | O11: 1.1353929 | P11: 1 | Q11: 1 | R11: 1 | S11: 1 | T11: 1
A12: 2028 | B12: 1 | C12: 1 | D12: 1 | E12: 1 | F12: 1 | G12: 1 | H12: 1 | I12: 1 | J12: 1 | K12: 1 | L12: 1 | M12: 1 | N12: 1 | O12: 1.122285 | P12: 1 | Q12: 1 | R12: 1 | S12: 1 | T12: 1
A13: 2029 | B13: 1 | C13: 1 | D13: 1 | E13: 1 | F13: 1 | G13: 1 | H13: 1 | I13: 1 | J13: 1 | K13: 1 | L13: 1 | M13: 1 | N13: 1 | O13: 1.109177 | P13: 1 | Q13: 1 | R13: 1 | S13: 1 | T13: 1
A14: 2030 | B14: 1 | C14: 1 | D14: 1 | E14: 1 | F14: 1 | G14: 1 | H14: 1 | I14: 1 | J14: 1 | K14: 1 | L14: 1 | M14: 1 | N14: 1 | O14: 1.0960691 | P14: 1 | Q14: 1 | R14: 1 | S14: 1 | T14: 1
A15: 2031 | B15: 1 | C15: 1 | D15: 1 | E15: 1 | F15: 1 | G15: 1 | H15: 1 | I15: 1 | J15: 1 | K15: 1 | L15: 1 | M15: 1 | N15: 1 | O15: 1.0918079 | P15: 1 | Q15: 1 | R15: 1 | S15: 1 | T15: 1
A16: 2032 | B16: 1 | C16: 1 | D16: 1 | E16: 1 | F16: 1 | G16: 1 | H16: 1 | I16: 1 | J16: 1 | K16: 1 | L16: 1 | M16: 1 | N16: 1 | O16: 1.0875467 | P16: 1 | Q16: 1 | R16: 1 | S16: 1 | T16: 1
A17: 2033 | B17: 1 | C17: 1 | D17: 1 | E17: 1 | F17: 1 | G17: 1 | H17: 1 | I17: 1 | J17: 1 | K17: 1 | L17: 1 | M17: 1 | N17: 1 | O17: 1.0832856 | P17: 1 | Q17: 1 | R17: 1 | S17: 1 | T17: 1
A18: 2034 | B18: 1 | C18: 1 | D18: 1 | E18: 1 | F18: 1 | G18: 1 | H18: 1 | I18: 1 | J18: 1 | K18: 1 | L18: 1 | M18: 1 | N18: 1 | O18: 1.0790244 | P18: 1 | Q18: 1 | R18: 1 | S18: 1 | T18: 1
A19: 2035 | B19: 1 | C19: 1 | D19: 1 | E19: 1 | F19: 1 | G19: 1 | H19: 1 | I19: 1 | J19: 1 | K19: 1 | L19: 1 | M19: 1 | N19: 1 | O19: 1.0747632 | P19: 1 | Q19: 1 | R19: 1 | S19: 1 | T19: 1
A20: 2036 | B20: 1 | C20: 1 | D20: 1 | E20: 1 | F20: 1 | G20: 1 | H20: 1 | I20: 1 | J20: 1 | K20: 1 | L20: 1 | M20: 1 | N20: 1 | O20: 1.0708813 | P20: 1 | Q20: 1 | R20: 1 | S20: 1 | T20: 1
A21: 2037 | B21: 1 | C21: 1 | D21: 1 | E21: 1 | F21: 1 | G21: 1 | H21: 1 | I21: 1 | J21: 1 | K21: 1 | L21: 1 | M21: 1 | N21: 1 | O21: 1.0669993 | P21: 1 | Q21: 1 | R21: 1 | S21: 1 | T21: 1
A22: 2038 | B22: 1 | C22: 1 | D22: 1 | E22: 1 | F22: 1 | G22: 1 | H22: 1 | I22: 1 | J22: 1 | K22: 1 | L22: 1 | M22: 1 | N22: 1 | O22: 1.0631173 | P22: 1 | Q22: 1 | R22: 1 | S22: 1 | T22: 1
... A44: 2060 | B44: 1 | C44: 1 | D44: 1 | E44: 1 | F44: 1 | G44: 1 | H44: 1 | I44: 1 | J44: 1 | K44: 1 | L44: 1 | M44: 1 | N44: 1 | O44: 1 | P44: 1 | Q44: 1 | R44: 1 | S44: 1 | T44: 1

Sheet FC
A1: 0 | B1: DICE | C1: NGICE | D1: BEVF730 | E1: BEVE510 | F1: EDPHEV | G1: ELPHEV | H1: FCEV | I1: MICE | J1: H2ICE70
A2: h_trailer_hwl | B2: 38 | C2: 72 | D2: 135 | E2: 135 | F2: =B2*0.85 -> 32.3 | G2: =C2*0.85 -> 61.2 | H2: 10 | I2: 110 | J2: 11
A3: h_trailer_hws | B3: 38 | C3: 72 | D3: 135 | E3: 135 | F3: =B3*0.85 -> 32.3 | G3: =C3*0.85 -> 61.2 | H3: 10 | I3: 110 | J3: 11
A4: h_trailer_hwm | B4: 38 | C4: 72 | D4: 135 | E4: 135 | F4: =B4*0.85 -> 32.3 | G4: =C4*0.85 -> 61.2 | H4: 10 | I4: 110 | J4: 11
I19: 全面了解吉利甲醇重卡：性能、使用与未来展望
I20: 晋南钢铁及佛山氢燃料电池重卡分析（附31页报告）
I21: 氢气发动机有前途吗？这几款欧洲最先进的氢内燃机重卡告诉你-有驾

Sheet cargoFC1
B1: DICE | C1: NGICE | D1: BEVF282 | E1: BEVF423 | F1: BEVE282 | G1: BEVF729 | H1: BEVE512 | I1: BEVU729 | J1: PHEV | K1: EDPHEV | L1: ELPHEV | M1: FCEV | N1: MICE | O1: EDICE | P1: ELICE | Q1: H2ICE35 | R1: H2ICE70 | S1: NH3ICE | T1: HNICE
A2: 0 | B2: =15/42*FC!B4 -> 13.571429 | C2: =15/42*FC!C4 -> 25.714286 | D2: =D3*B2/B3 -> 47.535652 | E2: =E3*B2/B3 -> 48.469388 | F2: =D2 -> 47.535652 | G2: =G3*B2/B3 -> 51.116492 | H2: =H3*B2/B3 -> 49.350649 | I2: =G2 -> 51.116492 | J2: =15/42*FC!F2 -> 11.535714 | K2: =O2 -> 13.5 | L2: =P2 -> 13.5 | M2: =15/42*FC!H4 -> 3.5714286 | N2: =15/42*FC!I4 -> 39.285714 | O2: =P2 -> 13.5 | P2: 13.5 | Q2: =R2 -> 3.1722689 | R2: =R3*B3/B4 -> 3.1722689 | S2: 6.4285714 | T2: 6.4285714
A3: 0.1 | B3: 15.1 | C3: =B3*C2/B2 -> 28.610526 | D3: =D4*B3/B4 -> 52.889667 | E3: =E4*B3/B4 -> 53.928571 | F3: =D3 -> 52.889667 | G3: =G4*B3/B4 -> 56.873823 | H3: =H4*B3/B4 -> 54.909091 | I3: =G3 -> 56.873823 | J3: =D3*J2/D2 -> 12.835 | K3: =O3 -> 13.59 | L3: =P3 -> 13.59 | M3: =B3*M2/B2 -> 3.9736842 | N3: =B3*N2/B2 -> 43.710526 | O3: =P3 -> 13.59 | P3: 13.59 | Q3: =R3 -> 3.1932773 | R3: =R4*B4/B5 -> 3.1932773 | S3: 6.4714286 | T3: 6.4714286
A4: 0.2 | B4: 15.2 | C4: =B4*C3/B3 -> 28.8 | D4: =D5*B4/B5 -> 53.23993 | E4: =E5*B4/B5 -> 54.285714 | F4: =D4 -> 53.23993 | G4: =G5*B4/B5 -> 57.250471 | H4: =H5*B4/B5 -> 55.272727 | I4: =G4 -> 57.250471 | J4: =D4*J3/D3 -> 12.92 | K4: =O4 -> 13.68 | L4: =P4 -> 13.68 | M4: =B4*M3/B3 -> 4 | N4: =B4*N3/B3 -> 44 | O4: =P4 -> 13.68 | P4: 13.68 | Q4: =R4 -> 3.2142857 | R4: =R5*B5/B6 -> 3.2142857 | S4: 6.5142857 | T4: 6.5142857
A5: 0.3 | B5: 15.3 | C5: =B5*C4/B4 -> 28.989474 | D5: =D6*B5/B6 -> 53.590193 | E5: =E6*B5/B6 -> 54.642857 | F5: =D5 -> 53.590193 | G5: =G6*B5/B6 -> 57.627119 | H5: =H6*B5/B6 -> 55.636364 | I5: =G5 -> 57.627119 | J5: =D5*J4/D4 -> 13.005 | K5: =O5 -> 13.77 | L5: =P5 -> 13.77 | M5: =B5*M4/B4 -> 4.0263158 | N5: =B5*N4/B4 -> 44.289474 | O5: =P5 -> 13.77 | P5: 13.77 | Q5: =R5 -> 3.2352941 | R5: =R6*B6/B7 -> 3.2352941 | S5: 6.5571429 | T5: 6.5571429
A6: 0.4 | B6: 15.4 | C6: =B6*C5/B5 -> 29.178947 | D6: =D7*B6/B7 -> 53.940455 | E6: =E7*B6/B7 -> 55 | F6: =D6 -> 53.940455 | G6: =G7*B6/B7 -> 58.003766 | H6: =H7*B6/B7 -> 56 | I6: =G6 -> 58.003766 | J6: =D6*J5/D5 -> 13.09 | K6: =O6 -> 13.86 | L6: =P6 -> 13.86 | M6: =B6*M5/B5 -> 4.0526316 | N6: =B6*N5/B5 -> 44.578947 | O6: =P6 -> 13.86 | P6: 13.86 | Q6: =R6 -> 3.2563025 | R6: =R7*B7/B8 -> 3.2563025 | S6: 6.6 | T6: 6.6
A7: 0.5 | B7: 15.5 | C7: =B7*C6/B6 -> 29.368421 | D7: =D8*B7/B8 -> 54.290718 | E7: =E8*B7/B8 -> 55.357143 | F7: =D7 -> 54.290718 | G7: =G8*B7/B8 -> 58.380414 | H7: =H8*B7/B8 -> 56.363636 | I7: =G7 -> 58.380414 | J7: =D7*J6/D6 -> 13.175 | K7: =O7 -> 13.95 | L7: =P7 -> 13.95 | M7: =B7*M6/B6 -> 4.0789474 | N7: =B7*N6/B6 -> 44.868421 | O7: =P7 -> 13.95 | P7: 13.95 | Q7: =R7 -> 3.2773109 | R7: =R8*B8/B9 -> 3.2773109 | S7: 6.6428571 | T7: 6.6428571
A8: 0.6 | B8: 15.6 | C8: =B8*C7/B7 -> 29.557895 | D8: =D9*B8/B9 -> 54.640981 | E8: =E9*B8/B9 -> 55.714286 | F8: =D8 -> 54.640981 | G8: =G9*B8/B9 -> 58.757062 | H8: =H9*B8/B9 -> 56.727273 | I8: =G8 -> 58.757062 | J8: =D8*J7/D7 -> 13.26 | K8: =O8 -> 14.04 | L8: =P8 -> 14.04 | M8: =B8*M7/B7 -> 4.1052632 | N8: =B8*N7/B7 -> 45.157895 | O8: =P8 -> 14.04 | P8: 14.04 | Q8: =R8 -> 3.2983193 | R8: =R9*B9/B10 -> 3.2983193 | S8: 6.6857143 | T8: 6.6857143
A9: 0.7 | B9: 15.7 | C9: =B9*C8/B8 -> 29.747368 | D9: =D10*B9/B10 -> 54.991243 | E9: =E10*B9/B10 -> 56.071429 | F9: =D9 -> 54.991243 | G9: =G10*B9/B10 -> 59.13371 | H9: =H10*B9/B10 -> 57.090909 | I9: =G9 -> 59.13371 | J9: =D9*J8/D8 -> 13.345 | K9: =O9 -> 14.13 | L9: =P9 -> 14.13 | M9: =B9*M8/B8 -> 4.1315789 | N9: =B9*N8/B8 -> 45.447368 | O9: =P9 -> 14.13 | P9: 14.13 | Q9: =R9 -> 3.3193277 | R9: =R10*B10/B11 -> 3.3193277 | S9: 6.7285714 | T9: 6.7285714
A10: 0.8 | B10: 15.8 | C10: =B10*C9/B9 -> 29.936842 | D10: =D11*B10/B11 -> 55.341506 | E10: =E11*B10/B11 -> 56.428571 | F10: =D10 -> 55.341506 | G10: =G11*B10/B11 -> 59.510358 | H10: =H11*B10/B11 -> 57.454545 | I10: =G10 -> 59.510358 | J10: =D10*J9/D9 -> 13.43 | K10: =O10 -> 14.22 | L10: =P10 -> 14.22 | M10: =B10*M9/B9 -> 4.1578947 | N10: =B10*N9/B9 -> 45.736842 | O10: =P10 -> 14.22 | P10: 14.22 | Q10: =R10 -> 3.3403361 | R10: =R11*B11/B12 -> 3.3403361 | S10: 6.7714286 | T10: 6.7714286
A11: 0.9 | B11: 15.9 | C11: =B11*C10/B10 -> 30.126316 | D11: =D12*B11/B12 -> 55.691769 | E11: =E12*B11/B12 -> 56.785714 | F11: =D11 -> 55.691769 | G11: =G12*B11/B12 -> 59.887006 | H11: =H12*B11/B12 -> 57.818182 | I11: =G11 -> 59.887006 | J11: =D11*J10/D10 -> 13.515 | K11: =O11 -> 14.31 | L11: =P11 -> 14.31 | M11: =B11*M10/B10 -> 4.1842105 | N11: =B11*N10/B10 -> 46.026316 | O11: =P11 -> 14.31 | P11: 14.31 | Q11: =R11 -> 3.3613445 | R11: =R12*B12/B13 -> 3.3613445 | S11: 6.8142857 | T11: 6.8142857
A12: 1 | B12: 16 | C12: =B12*C11/B11 -> 30.315789 | D12: =D13*B12/B13 -> 56.042032 | E12: =E13*B12/B13 -> 57.142857 | F12: =D12 -> 56.042032 | G12: =G13*B12/B13 -> 60.263653 | H12: =H13*B12/B13 -> 58.181818 | I12: =G12 -> 60.263653 | J12: =D12*J11/D11 -> 13.6 | K12: =O12 -> 14.4 | L12: =P12 -> 14.4 | M12: =B12*M11/B11 -> 4.2105263 | N12: =B12*N11/B11 -> 46.315789 | O12: =P12 -> 14.4 | P12: 14.4 | Q12: =R12 -> 3.3823529 | R12: =R13*B13/B14 -> 3.3823529 | S12: 6.8571428 | T12: 6.8571428
A13: 1.1 | B13: 16.1 | C13: =B13*C12/B12 -> 30.505263 | D13: =D14*B13/B14 -> 56.392294 | E13: =E14*B13/B14 -> 57.5 | F13: =D13 -> 56.392294 | G13: =G14*B13/B14 -> 60.640301 | H13: =H14*B13/B14 -> 58.545455 | I13: =G13 -> 60.640301 | J13: =D13*J12/D12 -> 13.685 | K13: =O13 -> 14.49 | L13: =P13 -> 14.49 | M13: =B13*M12/B12 -> 4.2368421 | N13: =B13*N12/B12 -> 46.605263 | O13: =P13 -> 14.49 | P13: 14.49 | Q13: =R13 -> 3.4033613 | R13: =R14*B14/B15 -> 3.4033613 | S13: 6.9 | T13: 6.9
A14: 1.2 | B14: 16.2 | C14: =B14*C13/B13 -> 30.694737 | D14: =D15*B14/B15 -> 56.742557 | E14: =E15*B14/B15 -> 57.857143 | F14: =D14 -> 56.742557 | G14: =G15*B14/B15 -> 61.016949 | H14: =H15*B14/B15 -> 58.909091 | I14: =G14 -> 61.016949 | J14: =D14*J13/D13 -> 13.77 | K14: =O14 -> 14.58 | L14: =P14 -> 14.58 | M14: =B14*M13/B13 -> 4.2631579 | N14: =B14*N13/B13 -> 46.894737 | O14: =P14 -> 14.58 | P14: 14.58 | Q14: =R14 -> 3.4243697 | R14: =R15*B15/B16 -> 3.4243697 | S14: 6.9428571 | T14: 6.9428571
... A101: 9.9 | B101: 24.9 | C101: =B101*C100/B100 -> 47.178947 | D101: =D102*B101/B102 -> 87.215412 | E101: =E102*B101/B102 -> 88.928571 | F101: =D101 -> 87.215412 | G101: =G102*B101/B102 -> 93.785311 | H101: =H102*B101/B102 -> 90.545455 | I101: =G101 -> 93.785311 | J101: =D101*J100/D100 -> 21.165 | K101: =O101 -> 22.41 | L101: =P101 -> 22.41 | M101: =B101*M100/B100 -> 6.5526316 | N101: =B101*N100/B100 -> 72.078947 | O101: =P101 -> 22.41 | P101: 22.41 | Q101: =R101 -> 4.7519008 | R101: =R102*B102/B103 -> 4.7519008 | S101: 10.671428 | T101: 10.671428
A102: 10 | B102: =25/42*FC!B4 -> 22.619048 | C102: =B102*C101/B101 -> 42.857143 | D102: =D103*B102/B103 -> 79.226086 | E102: =E103*B102/B103 -> 80.782313 | F102: =D102 -> 79.226086 | G102: =G103*B102/B103 -> 85.194153 | H102: =H103*B102/B103 -> 82.251082 | I102: =G102 -> 85.194153 | J102: =D102*J101/D101 -> 19.22619 | K102: =O102 -> 22.5 | L102: =P102 -> 22.5 | M102: =B102*M101/B101 -> 5.952381 | N102: =B102*N101/B101 -> 65.47619 | O102: =P102 -> 22.5 | P102: 22.5 | Q102: =R102 -> 5.2731092 | R102: =R103*B103/B104 -> 5.2731092 | S102: 10.714286 | T102: 10.714286
A103: 10.1 | B103: 25.1 | C103: =B103*C102/B102 -> 47.557895 | D103: =D104*B103/B104 -> 87.915937 | E103: =E104*B103/B104 -> 89.642857 | F103: =D103 -> 87.915937 | G103: =G104*B103/B104 -> 94.538606 | H103: =H104*B103/B104 -> 91.272727 | I103: =G103 -> 94.538606 | J103: =D103*J102/D102 -> 21.335 | K103: =O103 -> 22.59 | L103: =P103 -> 22.59 | M103: =B103*M102/B102 -> 6.6052632 | N103: =B103*N102/B102 -> 72.657895 | O103: =P103 -> 22.59 | P103: 22.59 | Q103: =R103 -> 5.2941176 | R103: =R104*B104/B105 -> 5.2941176 | S103: 10.757143 | T103: 10.757143
A104: 10.2 | B104: 25.2 | C104: =B104*C103/B103 -> 47.747368 | D104: =D105*B104/B105 -> 88.2662 | E104: =E105*B104/B105 -> 90 | F104: =D104 -> 88.2662 | G104: =G105*B104/B105 -> 94.915254 | H104: =H105*B104/B105 -> 91.636364 | I104: =G104 -> 94.915254 | J104: =D104*J103/D103 -> 21.42 | K104: =O104 -> 22.68 | L104: =P104 -> 22.68 | M104: =B104*M103/B103 -> 6.6315789 | N104: =B104*N103/B103 -> 72.947368 | O104: =P104 -> 22.68 | P104: 22.68 | Q104: =R104 -> 5.3151261 | R104: =R105*B105/B106 -> 5.3151261 | S104: 10.8 | T104: 10.8
A105: 10.3 | B105: 25.3 | C105: =B105*C104/B104 -> 47.936842 | D105: =D106*B105/B106 -> 88.616462 | E105: =E106*B105/B106 -> 90.357143 | F105: =D105 -> 88.616462 | G105: =G106*B105/B106 -> 95.291902 | H105: =H106*B105/B106 -> 92 | I105: =G105 -> 95.291902 | J105: =D105*J104/D104 -> 21.505 | K105: =O105 -> 22.77 | L105: =P105 -> 22.77 | M105: =B105*M104/B104 -> 6.6578947 | N105: =B105*N104/B104 -> 73.236842 | O105: =P105 -> 22.77 | P105: 22.77 | Q105: =R105 -> 5.3361345 | R105: =R106*B106/B107 -> 5.3361345 | S105: 10.842857 | T105: 10.842857
A106: 10.4 | B106: 25.4 | C106: =B106*C105/B105 -> 48.126316 | D106: =D107*B106/B107 -> 88.966725 | E106: =E107*B106/B107 -> 90.714286 | F106: =D106 -> 88.966725 | G106: =G107*B106/B107 -> 95.66855 | H106: =H107*B106/B107 -> 92.363636 | I106: =G106 -> 95.66855 | J106: =D106*J105/D105 -> 21.59 | K106: =O106 -> 22.86 | L106: =P106 -> 22.86 | M106: =B106*M105/B105 -> 6.6842105 | N106: =B106*N105/B105 -> 73.526316 | O106: =P106 -> 22.86 | P106: 22.86 | Q106: =R106 -> 5.3571429 | R106: =R107*B107/B108 -> 5.3571429 | S106: 10.885714 | T106: 10.885714
A107: 10.5 | B107: 25.5 | C107: =B107*C106/B106 -> 48.315789 | D107: =D108*B107/B108 -> 89.316988 | E107: =E108*B107/B108 -> 91.071429 | F107: =D107 -> 89.316988 | G107: =G108*B107/B108 -> 96.045198 | H107: =H108*B107/B108 -> 92.727273 | I107: =G107 -> 96.045198 | J107: =D107*J106/D106 -> 21.675 | K107: =O107 -> 22.95 | L107: =P107 -> 22.95 | M107: =B107*M106/B106 -> 6.7105263 | N107: =B107*N106/B106 -> 73.815789 | O107: =P107 -> 22.95 | P107: 22.95 | Q107: =R107 -> 5.3781513 | R107: =R108*B108/B109 -> 5.3781513 | S107: 10.928571 | T107: 10.928571
A108: 10.6 | B108: 25.6 | C108: =B108*C107/B107 -> 48.505263 | D108: =D109*B108/B109 -> 89.66725 | E108: =E109*B108/B109 -> 91.428571 | F108: =D108 -> 89.66725 | G108: =G109*B108/B109 -> 96.421846 | H108: =H109*B108/B109 -> 93.090909 | I108: =G108 -> 96.421846 | J108: =D108*J107/D107 -> 21.76 | K108: =O108 -> 23.04 | L108: =P108 -> 23.04 | M108: =B108*M107/B107 -> 6.7368421 | N108: =B108*N107/B107 -> 74.105263 | O108: =P108 -> 23.04 | P108: 23.04 | Q108: =R108 -> 5.3991597 | R108: =R109*B109/B110 -> 5.3991597 | S108: 10.971428 | T108: 10.971428
A109: 10.7 | B109: 25.7 | C109: =B109*C108/B108 -> 48.694737 | D109: =D110*B109/B110 -> 90.017513 | E109: =E110*B109/B110 -> 91.785714 | F109: =D109 -> 90.017513 | G109: =G110*B109/B110 -> 96.798493 | H109: =H110*B109/B110 -> 93.454545 | I109: =G109 -> 96.798493 | J109: =D109*J108/D108 -> 21.845 | K109: =O109 -> 23.129999 | L109: =P109 -> 23.129999 | M109: =B109*M108/B108 -> 6.7631579 | N109: =B109*N108/B108 -> 74.394737 | O109: =P109 -> 23.129999 | P109: 23.129999 | Q109: =R109 -> 5.4201681 | R109: =R110*B110/B111 -> 5.4201681 | S109: 11.014285 | T109: 11.014285
A110: 10.8 | B110: 25.8 | C110: =B110*C109/B109 -> 48.884211 | D110: =D111*B110/B111 -> 90.367776 | E110: =E111*B110/B111 -> 92.142857 | F110: =D110 -> 90.367776 | G110: =G111*B110/B111 -> 97.175141 | H110: =H111*B110/B111 -> 93.818182 | I110: =G110 -> 97.175141 | J110: =D110*J109/D109 -> 21.93 | K110: =O110 -> 23.219999 | L110: =P110 -> 23.219999 | M110: =B110*M109/B109 -> 6.7894737 | N110: =B110*N109/B109 -> 74.684211 | O110: =P110 -> 23.219999 | P110: 23.219999 | Q110: =R110 -> 5.4411765 | R110: =R111*B111/B112 -> 5.4411765 | S110: 11.057143 | T110: 11.057143
A111: 10.9 | B111: 25.9 | C111: =B111*C110/B110 -> 49.073684 | D111: =D112*B111/B112 -> 90.718039 | E111: =E112*B111/B112 -> 92.5 | F111: =D111 -> 90.718039 | G111: =G112*B111/B112 -> 97.551789 | H111: =H112*B111/B112 -> 94.181818 | I111: =G111 -> 97.551789 | J111: =D111*J110/D110 -> 22.015 | K111: =O111 -> 23.309999 | L111: =P111 -> 23.309999 | M111: =B111*M110/B110 -> 6.8157895 | N111: =B111*N110/B110 -> 74.973684 | O111: =P111 -> 23.309999 | P111: 23.309999 | Q111: =R111 -> 5.4621849 | R111: =R112*B112/B113 -> 5.4621849 | S111: 11.1 | T111: 11.1
A112: 11 | B112: 26 | C112: =B112*C111/B111 -> 49.263158 | D112: =D113*B112/B113 -> 91.068301 | E112: =E113*B112/B113 -> 92.857143 | F112: =D112 -> 91.068301 | G112: =G113*B112/B113 -> 97.928437 | H112: =H113*B112/B113 -> 94.545455 | I112: =G112 -> 97.928437 | J112: =D112*J111/D111 -> 22.1 | K112: =O112 -> 23.399999 | L112: =P112 -> 23.399999 | M112: =B112*M111/B111 -> 6.8421053 | N112: =B112*N111/B111 -> 75.263158 | O112: =P112 -> 23.399999 | P112: 23.399999 | Q112: =R112 -> 5.4831933 | R112: =R113*B113/B114 -> 5.4831933 | S112: 11.142857 | T112: 11.142857
A113: 11.1 | B113: 26.1 | C113: =B113*C112/B112 -> 49.452632 | D113: =D114*B113/B114 -> 91.418564 | E113: =E114*B113/B114 -> 93.214286 | F113: =D113 -> 91.418564 | G113: =G114*B113/B114 -> 98.305085 | H113: =H114*B113/B114 -> 94.909091 | I113: =G113 -> 98.305085 | J113: =D113*J112/D112 -> 22.185 | K113: =O113 -> 23.489999 | L113: =P113 -> 23.489999 | M113: =B113*M112/B112 -> 6.8684211 | N113: =B113*N112/B112 -> 75.552632 | O113: =P113 -> 23.489999 | P113: 23.489999 | Q113: =R113 -> 5.5042017 | R113: =R114*B114/B115 -> 5.5042017 | S113: 11.185714 | T113: 11.185714
A114: 11.2 | B114: 26.2 | C114: =B114*C113/B113 -> 49.642105 | D114: =D115*B114/B115 -> 91.768827 | E114: =E115*B114/B115 -> 93.571429 | F114: =D114 -> 91.768827 | G114: =G115*B114/B115 -> 98.681733 | H114: =H115*B114/B115 -> 95.272727 | I114: =G114 -> 98.681733 | J114: =D114*J113/D113 -> 22.27 | K114: =O114 -> 23.579999 | L114: =P114 -> 23.579999 | M114: =B114*M113/B113 -> 6.8947368 | N114: =B114*N113/B113 -> 75.842105 | O114: =P114 -> 23.579999 | P114: 23.579999 | Q114: =R114 -> 5.5252101 | R114: =R115*B115/B116 -> 5.5252101 | S114: 11.228571 | T114: 11.228571
... A201: 19.9 | B201: 34.9 | C201: =B201*C200/B200 -> 66.126316 | D201: =D202*B201/B202 -> 122.24168 | E201: =E202*B201/B202 -> 124.64286 | F201: =D201 -> 122.24168 | G201: =G202*B201/B202 -> 131.45009 | H201: =H202*B201/B202 -> 126.90909 | I201: =G201 -> 131.45009 | J201: =D201*J200/D200 -> 29.665 | K201: =O201 -> 31.409993 | L201: =P201 -> 31.409993 | M201: =B201*M200/B200 -> 9.1842105 | N201: =B201*N200/B200 -> 101.02632 | O201: =P201 -> 31.409993 | P201: 31.409993 | Q201: =R201 -> 6.6526611 | R201: =R202*B202/B203 -> 6.6526611 | S201: 14.957139 | T201: 14.957139
A202: 20 | B202: =35/42*FC!B4 -> 31.666667 | C202: =B202*C201/B201 -> 60 | D202: =D203*B202/B203 -> 110.91652 | E202: =E203*B202/B203 -> 113.09524 | F202: =D202 -> 110.91652 | G202: =G203*B202/B203 -> 119.27181 | H202: =H203*B202/B203 -> 115.15152 | I202: =G202 -> 119.27181 | J202: =D202*J201/D201 -> 26.916667 | K202: =O202 -> 31.5 | L202: =P202 -> 31.5 | M202: =B202*M201/B201 -> 8.3333333 | N202: =B202*N201/B201 -> 91.666667 | O202: =P202 -> 31.5 | P202: 31.5 | Q202: =R202 -> 7.3676471 | R202: =R203*B203/B204 -> 7.3676471 | S202: 15 | T202: 15
A203: 20.1 | B203: 35.07 | C203: =B203*C202/B202 -> 66.448421 | D203: =D204*B203/B204 -> 122.83713 | E203: =E204*B203/B204 -> 125.25 | F203: =D203 -> 122.83713 | G203: =G204*B203/B204 -> 132.0904 | H203: =H204*B203/B204 -> 127.52727 | I203: =G203 -> 132.0904 | J203: =D203*J202/D202 -> 29.8095 | K203: =O203 -> 31.563 | L203: =P203 -> 31.563 | M203: =B203*M202/B202 -> 9.2289474 | N203: =B203*N202/B202 -> 101.51842 | O203: =P203 -> 31.563 | P203: 31.563 | Q203: =R203 -> 7.3823529 | R203: =R204*B204/B205 -> 7.3823529 | S203: 15.03 | T203: 15.03
A204: 20.2 | B204: 35.14 | C204: =B204*C203/B203 -> 66.581053 | D204: =D205*B204/B205 -> 123.08231 | E204: =E205*B204/B205 -> 125.5 | F204: =D204 -> 123.08231 | G204: =G205*B204/B205 -> 132.35405 | H204: =H205*B204/B205 -> 127.78182 | I204: =G204 -> 132.35405 | J204: =D204*J203/D203 -> 29.869 | K204: =O204 -> 31.626 | L204: =P204 -> 31.626 | M204: =B204*M203/B203 -> 9.2473684 | N204: =B204*N203/B203 -> 101.72105 | O204: =P204 -> 31.626 | P204: 31.626 | Q204: =R204 -> 7.3970588 | R204: =R205*B205/B206 -> 7.3970588 | S204: 15.06 | T204: 15.06
A205: 20.3 | B205: 35.21 | C205: =B205*C204/B204 -> 66.713684 | D205: =D206*B205/B206 -> 123.3275 | E205: =E206*B205/B206 -> 125.75 | F205: =D205 -> 123.3275 | G205: =G206*B205/B206 -> 132.6177 | H205: =H206*B205/B206 -> 128.03636 | I205: =G205 -> 132.6177 | J205: =D205*J204/D204 -> 29.9285 | K205: =O205 -> 31.689 | L205: =P205 -> 31.689 | M205: =B205*M204/B204 -> 9.2657895 | N205: =B205*N204/B204 -> 101.92368 | O205: =P205 -> 31.689 | P205: 31.689 | Q205: =R205 -> 7.4117647 | R205: =R206*B206/B207 -> 7.4117647 | S205: 15.09 | T205: 15.09
A206: 20.4 | B206: 35.28 | C206: =B206*C205/B205 -> 66.846316 | D206: =D207*B206/B207 -> 123.57268 | E206: =E207*B206/B207 -> 126 | F206: =D206 -> 123.57268 | G206: =G207*B206/B207 -> 132.88136 | H206: =H207*B206/B207 -> 128.29091 | I206: =G206 -> 132.88136 | J206: =D206*J205/D205 -> 29.988 | K206: =O206 -> 31.752 | L206: =P206 -> 31.752 | M206: =B206*M205/B205 -> 9.2842105 | N206: =B206*N205/B205 -> 102.12632 | O206: =P206 -> 31.752 | P206: 31.752 | Q206: =R206 -> 7.4264706 | R206: =R207*B207/B208 -> 7.4264706 | S206: 15.12 | T206: 15.12
A207: 20.5 | B207: 35.35 | C207: =B207*C206/B206 -> 66.978947 | D207: =D208*B207/B208 -> 123.81786 | E207: =E208*B207/B208 -> 126.25 | F207: =D207 -> 123.81786 | G207: =G208*B207/B208 -> 133.14501 | H207: =H208*B207/B208 -> 128.54545 | I207: =G207 -> 133.14501 | J207: =D207*J206/D206 -> 30.0475 | K207: =O207 -> 31.815 | L207: =P207 -> 31.815 | M207: =B207*M206/B206 -> 9.3026316 | N207: =B207*N206/B206 -> 102.32895 | O207: =P207 -> 31.815 | P207: 31.815 | Q207: =R207 -> 7.4411765 | R207: =R208*B208/B209 -> 7.4411765 | S207: 15.15 | T207: 15.15
A208: 20.6 | B208: 35.42 | C208: =B208*C207/B207 -> 67.111579 | D208: =D209*B208/B209 -> 124.06305 | E208: =E209*B208/B209 -> 126.5 | F208: =D208 -> 124.06305 | G208: =G209*B208/B209 -> 133.40866 | H208: =H209*B208/B209 -> 128.8 | I208: =G208 -> 133.40866 | J208: =D208*J207/D207 -> 30.107 | K208: =O208 -> 31.878 | L208: =P208 -> 31.878 | M208: =B208*M207/B207 -> 9.3210526 | N208: =B208*N207/B207 -> 102.53158 | O208: =P208 -> 31.878 | P208: 31.878 | Q208: =R208 -> 7.4558824 | R208: =R209*B209/B210 -> 7.4558824 | S208: 15.18 | T208: 15.18
A209: 20.7 | B209: 35.49 | C209: =B209*C208/B208 -> 67.244211 | D209: =D210*B209/B210 -> 124.30823 | E209: =E210*B209/B210 -> 126.75 | F209: =D209 -> 124.30823 | G209: =G210*B209/B210 -> 133.67232 | H209: =H210*B209/B210 -> 129.05455 | I209: =G209 -> 133.67232 | J209: =D209*J208/D208 -> 30.1665 | K209: =O209 -> 31.941 | L209: =P209 -> 31.941 | M209: =B209*M208/B208 -> 9.3394737 | N209: =B209*N208/B208 -> 102.73421 | O209: =P209 -> 31.941 | P209: 31.941 | Q209: =R209 -> 7.4705882 | R209: =R210*B210/B211 -> 7.4705882 | S209: 15.21 | T209: 15.21
A210: 20.8 | B210: 35.56 | C210: =B210*C209/B209 -> 67.376842 | D210: =D211*B210/B211 -> 124.55342 | E210: =E211*B210/B211 -> 127 | F210: =D210 -> 124.55342 | G210: =G211*B210/B211 -> 133.93597 | H210: =H211*B210/B211 -> 129.30909 | I210: =G210 -> 133.93597 | J210: =D210*J209/D209 -> 30.226 | K210: =O210 -> 32.004 | L210: =P210 -> 32.004 | M210: =B210*M209/B209 -> 9.3578947 | N210: =B210*N209/B209 -> 102.93684 | O210: =P210 -> 32.004 | P210: 32.004 | Q210: =R210 -> 7.4852941 | R210: =R211*B211/B212 -> 7.4852941 | S210: 15.24 | T210: 15.24
A211: 20.9 | B211: 35.63 | C211: =B211*C210/B210 -> 67.509474 | D211: =D212*B211/B212 -> 124.7986 | E211: =E212*B211/B212 -> 127.25 | F211: =D211 -> 124.7986 | G211: =G212*B211/B212 -> 134.19962 | H211: =H212*B211/B212 -> 129.56364 | I211: =G211 -> 134.19962 | J211: =D211*J210/D210 -> 30.2855 | K211: =O211 -> 32.067 | L211: =P211 -> 32.067 | M211: =B211*M210/B210 -> 9.3763158 | N211: =B211*N210/B210 -> 103.13947 | O211: =P211 -> 32.067 | P211: 32.067 | Q211: =R211 -> 7.5 | R211: =R212*B212/B213 -> 7.5 | S211: 15.27 | T211: 15.27
A212: 21 | B212: 35.7 | C212: =B212*C211/B211 -> 67.642105 | D212: =D213*B212/B213 -> 125.04378 | E212: =E213*B212/B213 -> 127.5 | F212: =D212 -> 125.04378 | G212: =G213*B212/B213 -> 134.46328 | H212: =H213*B212/B213 -> 129.81818 | I212: =G212 -> 134.46328 | J212: =D212*J211/D211 -> 30.345 | K212: =O212 -> 32.13 | L212: =P212 -> 32.13 | M212: =B212*M211/B211 -> 9.3947368 | N212: =B212*N211/B211 -> 103.34211 | O212: =P212 -> 32.13 | P212: 32.13 | Q212: =R212 -> 7.5147059 | R212: =R213*B213/B214 -> 7.5147059 | S212: 15.3 | T212: 15.3
...

Sheet maxcargo1
B1: DICE | C1: NGICE | D1: BEVF282 | E1: BEVF423 | F1: BEVE282 | G1: BEVF729 | H1: BEVE512 | I1: BEVU729 | J1: PHEV | K1: EDPHEV | L1: ELPHEV | M1: FCEV | N1: MICE | O1: EDICE | P1: ELICE | Q1: H2ICE35 | R1: H2ICE70 | S1: NH3ICE | T1: HNICE
B2: =totalmass!B2-cubeweight!B2 -> 40.195 | C2: =totalmass!C2-cubeweight!C2 -> 39.6 | D2: =totalmass!D2-cubeweight!D2 -> 38.1 | E2: =totalmass!E2-cubeweight!E2 -> 37.344 | F2: =totalmass!F2-cubeweight!F2 -> 36.84 | G2: =totalmass!G2-cubeweight!G2 -> 36.112 | H2: =totalmass!H2-cubeweight!H2 -> 37.344 | I2: =totalmass!J2-cubeweight!J2 -> 35.16 | J2: =totalmass!K2-cubeweight!K2 -> 38.9 | K2: =J2 -> 38.9 | L2: =K2 -> 38.9 | M2: =totalmass!N2-cubeweight!N2 -> 37.34 | N2: =totalmass!O2-cubeweight!O2 -> 39.5 | O2: 31.195 | P2: =totalmass!Q2-cubeweight!Q2 -> 40.195 | Q2: =totalmass!R2-cubeweight!R2 -> 40.195 | R2: =totalmass!S2-cubeweight!S2 -> 38.88 | S2: =totalmass!T2-cubeweight!T2 -> 40.195 | T2: =totalmass!U2-cubeweight!U2 -> 40.195

Sheet findingtime1
B1: 黑龙江 | C1: 吉林 | D1: 辽宁 | E1: 北京 | F1: 天津 | G1: 河北 | H1: 山西 | I1: 内蒙古 | J1: 新疆 | K1: 甘肃 | L1: 陕西 | M1: 宁夏 | N1: 青海 | O1: 河南 | P1: 湖北 | Q1: 湖南 | R1: 上海 | S1: 江苏 | T1: 浙江 | U1: 山东 | V1: 安徽 | W1: 福建 | X1: 江西 | Y1: 四川 | Z1: 云南 | AA1: 重庆 | AB1: 贵州 | AC1: 西藏 | AD1: 广西 | AE1: 广东 | AF1: 海南
A2: DICE | B2: 0.1 | C2: 0.1 | D2: 0.1 | E2: 0.1 | F2: 0.1 | G2: 0.1 | H2: 0.1 | I2: 0.1 | J2: 0.1 | K2: 0.1 | L2: 0.1 | M2: 0.1 | N2: 0.1 | O2: 0.1 | P2: 0.1 | Q2: 0.1 | R2: 0.1 | S2: 0.1 | T2: 0.1 | U2: 0.1 | V2: 0.1 | W2: 0.1 | X2: 0.1 | Y2: 0.1 | Z2: 0.1 | AA2: 0.1 | AB2: 0.1 | AC2: 0.1 | AD2: 0.1 | AE2: 0.1 | AF2: 0.1
A3: NGICE | B3: 0.5 | C3: 0.5 | D3: 0.5 | E3: 0.5 | F3: 0.5 | G3: 0.5 | H3: 0.5 | I3: 0.5 | J3: 0.5 | K3: 0.5 | L3: 0.5 | M3: 0.5 | N3: 0.5 | O3: 0.5 | P3: 0.5 | Q3: 0.5 | R3: 0.5 | S3: 0.5 | T3: 0.5 | U3: 0.5 | V3: 0.5 | W3: 0.5 | X3: 0.5 | Y3: 0.5 | Z3: 0.5 | AA3: 0.5 | AB3: 0.5 | AC3: 0.5 | AD3: 0.5 | AE3: 0.5 | AF3: 0.5
A4: BEVF282 | B4: 0.5 | C4: 0.5 | D4: 0.5 | E4: 0.5 | F4: 0.5 | G4: 0.5 | H4: 0.5 | I4: 0.5 | J4: 0.5 | K4: 0.5 | L4: 0.5 | M4: 0.5 | N4: 0.5 | O4: 0.5 | P4: 0.5 | Q4: 0.5 | R4: 0.5 | S4: 0.5 | T4: 0.5 | U4: 0.5 | V4: 0.5 | W4: 0.5 | X4: 0.5 | Y4: 0.5 | Z4: 0.5 | AA4: 0.5 | AB4: 0.5 | AC4: 0.5 | AD4: 0.5 | AE4: 0.5 | AF4: 0.5
A5: BEVF423 | B5: 0.5 | C5: 0.5 | D5: 0.5 | E5: 0.5 | F5: 0.5 | G5: 0.5 | H5: 0.5 | I5: 0.5 | J5: 0.5 | K5: 0.5 | L5: 0.5 | M5: 0.5 | N5: 0.5 | O5: 0.5 | P5: 0.5 | Q5: 0.5 | R5: 0.5 | S5: 0.5 | T5: 0.5 | U5: 0.5 | V5: 0.5 | W5: 0.5 | X5: 0.5 | Y5: 0.5 | Z5: 0.5 | AA5: 0.5 | AB5: 0.5 | AC5: 0.5 | AD5: 0.5 | AE5: 0.5 | AF5: 0.5
A6: BEVE282 | B6: 0 | C6: 0 | D6: 0 | E6: 0 | F6: 0 | G6: 0 | H6: 0 | I6: 0 | J6: 0 | K6: 0 | L6: 0 | M6: 0 | N6: 0 | O6: 0 | P6: 0 | Q6: 0 | R6: 0 | S6: 0 | T6: 0 | U6: 0 | V6: 0 | W6: 0 | X6: 0 | Y6: 0 | Z6: 0 | AA6: 0 | AB6: 0 | AC6: 0 | AD6: 0 | AE6: 0 | AF6: 0
A7: BEVF729 | B7: 0.5 | C7: 0.5 | D7: 0.5 | E7: 0.5 | F7: 0.5 | G7: 0.5 | H7: 0.5 | I7: 0.5 | J7: 0.5 | K7: 0.5 | L7: 0.5 | M7: 0.5 | N7: 0.5 | O7: 0.5 | P7: 0.5 | Q7: 0.5 | R7: 0.5 | S7: 0.5 | T7: 0.5 | U7: 0.5 | V7: 0.5 | W7: 0.5 | X7: 0.5 | Y7: 0.5 | Z7: 0.5 | AA7: 0.5 | AB7: 0.5 | AC7: 0.5 | AD7: 0.5 | AE7: 0.5 | AF7: 0.5
A8: BEVE512 | B8: 0 | C8: 0 | D8: 0 | E8: 0 | F8: 0 | G8: 0 | H8: 0 | I8: 0 | J8: 0 | K8: 0 | L8: 0 | M8: 0 | N8: 0 | O8: 0 | P8: 0 | Q8: 0 | R8: 0 | S8: 0 | T8: 0 | U8: 0 | V8: 0 | W8: 0 | X8: 0 | Y8: 0 | Z8: 0 | AA8: 0 | AB8: 0 | AC8: 0 | AD8: 0 | AE8: 0 | AF8: 0
A9: BEVU729 | B9: 0.5 | C9: 0.5 | D9: 0.5 | E9: 0.5 | F9: 0.5 | G9: 0.5 | H9: 0.5 | I9: 0.5 | J9: 0.5 | K9: 0.5 | L9: 0.5 | M9: 0.5 | N9: 0.5 | O9: 0.5 | P9: 0.5 | Q9: 0.5 | R9: 0.5 | S9: 0.5 | T9: 0.5 | U9: 0.5 | V9: 0.5 | W9: 0.5 | X9: 0.5 | Y9: 0.5 | Z9: 0.5 | AA9: 0.5 | AB9: 0.5 | AC9: 0.5 | AD9: 0.5 | AE9: 0.5 | AF9: 0.5
A10: PHEV | B10: 0.3 | C10: 0.3 | D10: 0.3 | E10: 0.3 | F10: 0.3 | G10: 0.3 | H10: 0.3 | I10: 0.3 | J10: 0.3 | K10: 0.3 | L10: 0.3 | M10: 0.3 | N10: 0.3 | O10: 0.3 | P10: 0.3 | Q10: 0.3 | R10: 0.3 | S10: 0.3 | T10: 0.3 | U10: 0.3 | V10: 0.3 | W10: 0.3 | X10: 0.3 | Y10: 0.3 | Z10: 0.3 | AA10: 0.3 | AB10: 0.3 | AC10: 0.3 | AD10: 0.3 | AE10: 0.3 | AF10: 0.3
A11: EDPHEV | B11: =B16 -> 0.1 | C11: =C16 -> 0.1 | D11: =D16 -> 0.1 | E11: =E16 -> 0.1 | F11: =F16 -> 0.1 | G11: =G16 -> 0.1 | H11: =H16 -> 0.1 | I11: =I16 -> 0.1 | ... AF11: =AF16 -> 0.1
A12: ELPHEV | B12: =B17 -> 0.5 | C12: =C17 -> 0.5 | D12: =D17 -> 0.5 | E12: =E17 -> 0.5 | F12: =F17 -> 0.5 | G12: =G17 -> 0.5 | H12: =H17 -> 0.5 | I12: =I17 -> 0.5 | ... AF12: =AF17 -> 0.5
A13: FCPHEV | B13: 0.8 | C13: 0.8 | D13: 0.8 | E13: 0.8 | F13: 0.8 | G13: 0.8 | H13: 0.8 | I13: 0.8 | J13: 0.8 | K13: 0.8 | L13: 0.8 | M13: 0.8 | N13: 0.8 | O13: 0.8 | P13: 0.8 | Q13: 0.8 | R13: 0.8 | S13: 0.8 | T13: 0.8 | U13: 0.8 | V13: 0.8 | W13: 0.8 | X13: 0.8 | Y13: 0.8 | Z13: 0.8 | AA13: 0.8 | AB13: 0.8 | AC13: 0.8 | AD13: 0.8 | AE13: 0.8 | AF13: 0.8
A14: FCEV | B14: 0.8 | C14: 0.8 | D14: 0.8 | E14: 0.8 | F14: 0.8 | G14: 0.8 | H14: 0.8 | I14: 0.8 | J14: 0.8 | K14: 0.8 | L14: 0.8 | M14: 0.8 | N14: 0.8 | O14: 0.8 | P14: 0.8 | Q14: 0.8 | R14: 0.8 | S14: 0.8 | T14: 0.8 | U14: 0.8 | V14: 0.8 | W14: 0.8 | X14: 0.8 | Y14: 0.8 | Z14: 0.8 | AA14: 0.8 | AB14: 0.8 | AC14: 0.8 | AD14: 0.8 | AE14: 0.8 | AF14: 0.8
A15: MICE | B15: 1 | C15: 1 | D15: 1 | E15: 1 | F15: 1 | G15: 1 | H15: 1 | I15: 1 | J15: 1 | K15: 1 | L15: 1 | M15: 1 | N15: 1 | O15: 1 | P15: 1 | Q15: 1 | R15: 1 | S15: 1 | T15: 1 | U15: 1 | V15: 1 | W15: 1 | X15: 1 | Y15: 1 | Z15: 1 | AA15: 1 | AB15: 1 | AC15: 1 | AD15: 1 | AE15: 1 | AF15: 1
A16: EDICE | B16: =B2 -> 0.1 | C16: =C2 -> 0.1 | D16: =D2 -> 0.1 | E16: =E2 -> 0.1 | F16: =F2 -> 0.1 | G16: =G2 -> 0.1 | H16: =H2 -> 0.1 | I16: =I2 -> 0.1 | ... AF16: =AF2 -> 0.1
A17: ELICE | B17: =B3 -> 0.5 | C17: =C3 -> 0.5 | D17: =D3 -> 0.5 | E17: =E3 -> 0.5 | F17: =F3 -> 0.5 | G17: =G3 -> 0.5 | H17: =H3 -> 0.5 | I17: =I3 -> 0.5 | ... AF17: =AF3 -> 0.5
A18: H2ICE35 | B18: =B14 -> 0.8 | C18: =C14 -> 0.8 | D18: =D14 -> 0.8 | E18: =E14 -> 0.8 | F18: =F14 -> 0.8 | G18: =G14 -> 0.8 | H18: =H14 -> 0.8 | I18: =I14 -> 0.8 | ... AF18: =AF14 -> 0.8
A19: H2ICE70 | B19: =B14 -> 0.8 | C19: =C14 -> 0.8 | D19: =D14 -> 0.8 | E19: =E14 -> 0.8 | F19: =F14 -> 0.8 | G19: =G14 -> 0.8 | H19: =H14 -> 0.8 | I19: =I14 -> 0.8 | ... AF19: =AF14 -> 0.8
